Workbook
Name _Hlk42425552: 输入参数!$B$2

Sheet 输入参数
B1: 效益测算输入参数表
B2: 参数类别 | C2: 序号 | D2: 指标名称 | E2: 数值 | F2: 备注
B3: 关键参数 | C3: 1 | D3: 静态总投资（万元） | E3: =静态总投!E57 -> 15846.259
C4: 2 | D4: 首年理论上网小时数（小时） | E4: =E16*E18 -> 510
C5: 3 | D5: 限电率 | E5: 0
C6: 4 | D6: 首年上网小时数（小时） | E6: =E4*(1-E5) -> 510
D7: 不参与交易上网小时数 | E7: 0
D8: 参与交易上网小时数 | E8: =E6-E7 -> 510
C9: 5 | D9: 电价（元/千瓦时） | E9: 0.5868
D10: 是否考虑交易 | E10: 是
D11: 项目所在省份 | E11: 其他 | F11: 根据项目所在省份确定电价折减。
D12: 交易折减 | E12: 0 | F12: 折减数据参考手册数据，其他省份交易折减数据请手动填入。
D13: 交易电价（元/千瓦时） | E13: =E9-E12 -> 0.5868
D14: 充电电价（元/千瓦时） | E14: 0.2815
D15: 电价差(元/千瓦时) | E15: =E13-E14 -> 0.3053
D16: 调度次数 | E16: 255
B17: 必要参数 | C17: 6 | D17: 电化学储能装机容量（万千瓦） | E17: 10
D18: 电化学储能时长（小时） | E18: 2
C19: 7 | D19: 还款方式 | E19: 等额本息
C20: 8 | D20: 长期借款利率 | E20: =3% -> 0.03
C21: 9 | D21: 两个细则考核
C22: 10 | D22: 可抵扣增值税进项税（万元） | E22: ='表1-投资计划与资金筹措表'!D6*0.09 -> 1443.2772 | F22: 当采用直线折旧时，使用总投资进行估算，当采用分类折旧时，根据折旧情况计算。
C23: 11 | D23: 折旧方式 | E23: 分类折旧 | F23: 采用分类折旧法时，应在分类折旧表格中填写各类资产原值。
C24: 12 | D24: 送出条件 | E24: 包含20km以内高压送出线路及对侧间隔
D25: 送出线路电压 | E25: 330kV以下
D26: 运维费 | E26: 按参数取值 | F26: 选择手动输入时，具体金额填入手动输入参数表。
C27: 13 | D27: 是否为续建项目 | E27: 否 | F27: 自动计算定员。
D28: 原有项目规模 | E28: 0
D29: 定员（人） | E29: 4
C30: 14 | D30: 人工成本（万元/人） | E30: 33
C31: 15 | D31: 本单位已投运、在建项目规模（万千瓦） | E31: 0
D32: 其他费用（万元） | E32: 0
C33: 16 | D33: 保险费率 | E33: 0.0015
C34: 17 | D34: 销售税金及附加税率 | E34: 0.12 | F34: 邛崃市城市维护建设税7%+其他附加税5%
C35: 18 | D35: 所得税税率 | E35: 享受西部大开发优惠政策
B36: 可选参数 | C36: 19 | D36: 土地费用（万元） | E36: =(5+(静态总投!E7+静态总投!E8)*1.2%*70%)*30*666.667/10000 -> 35.200018 | F36: 如每年金额不同，此处填0，具体金额填入手动输入参数表。
C37: 20 | D37: 应列未列的其他成本费用 | E37: - | F37: 如存在应列未列的其他成本费用，请根据实际情况在手动输入参数表填写。
D38: 增值税补贴收入 | E38: 有 | F38: 如有增值税补贴收入，填“有”。 | H38: - | I38: - | J38: - | K38: - | L38: - | M38: - | N38: - | O38: - | P38: - | Q38: - | R38: - | S38: - | T38: - | U38: - | V38: - | W38: - | X38: - | Y38: - | Z38: - | AA38: - | AB38: -
B39: 评价结论 | C39: =财务指标及评价!B21 -> 项目运营期12年年均营业收入3175万元，年均利润总额230万元，年均净利润211万元，全投资财务内部收益率6.38%，资本金财务内部收益率17.97%，投资回收期9.2年。综上，项目收益情况较好，满足优先投资收益率标准。
B41: 注意事项 | C41: 1.采用分类折旧时，将固定资产分类情况填入分类折旧表。 2.如土地费用每年金额不同，请将每年对应的数据填入手动输入参数表。
...

Sheet 手动输入参数表
C2: 建设期 | D2: 计算期
C3: 第1年 | D3: 第2年 | E3: 第3年 | F3: 第4年 | G3: 第5年 | H3: 第6年 | I3: 第7年 | J3: 第8年 | K3: 第9年 | L3: 第10年 | M3: 第11年 | N3: 第12年 | O3: 第13年
C4: - | D4: - | E4: - | F4: - | G4: - | H4: - | I4: - | J4: - | K4: - | L4: - | M4: - | N4: - | O4: -
B5: 上网电量（万千瓦时） | C5: - | D5: ='表2-利润与利润分配表'!F15 -> 4016.4256 | E5: ='表2-利润与利润分配表'!G15 -> 3941.2884 | F5: ='表2-利润与利润分配表'!H15 -> 3872.9818 | G5: ='表2-利润与利润分配表'!I15 -> 3822.8903 | H5: ='表2-利润与利润分配表'!J15 -> 3765.9682 | I5: ='表2-利润与利润分配表'!K15 -> 3724.9843 | J5: ='表2-利润与利润分配表'!L15 -> 3674.8928 | K5: ='表2-利润与利润分配表'!M15 -> 3638.4626 | ... O5: ='表2-利润与利润分配表'!Q15 -> 3485.9113
C8: - | D8: - | E8: - | F8: - | G8: - | H8: - | I8: - | J8: - | K8: - | L8: - | M8: - | N8: - | O8: -
C9: - | D9: - | E9: - | F9: - | G9: - | H9: - | I9: - | J9: - | K9: - | L9: - | M9: - | N9: - | O9: -
C10: - | D10: - | E10: - | F10: - | G10: - | H10: - | I10: - | J10: - | K10: - | L10: - | M10: - | N10: - | O10: -
C11: - | D11: - | E11: - | F11: - | G11: - | H11: - | I11: - | J11: - | K11: - | L11: - | M11: - | N11: - | O11: -
C12: - | D12: - | E12: - | F12: - | G12: - | H12: - | I12: - | J12: - | K12: - | L12: - | M12: - | N12: - | O12: -
C13: - | D13: - | E13: - | F13: - | G13: - | H13: - | I13: - | J13: - | K13: - | L13: - | M13: - | N13: - | O13: -
B14: 折旧费（万元/年） | C14: - | D14: =分类折旧!I80 -> 1149.2888 | E14: =D14 -> 1149.2888 | F14: =E14 -> 1149.2888 | G14: =F14 -> 1149.2888 | H14: =G14 -> 1149.2888 | I14: =分类折旧!J80 -> 1149.2888 | J14: =分类折旧!K80 -> 1149.2888 | K14: =分类折旧!L80 -> 1149.2888 | L14: =分类折旧!M80 -> 1149.2888 | M14: =分类折旧!M80 -> 1149.2888 | N14: =分类折旧!N80 -> 1149.2888 | O14: =N14 -> 1149.2888
B15: 运维费（万元/年） | C15: - | D15: =运维费!C20 -> 78.349018 | E15: =运维费!D20 -> 84.186273 | F15: =运维费!E20 -> 84.186273 | G15: =运维费!F20 -> 84.186273 | H15: =运维费!G20 -> 90.023528 | I15: =运维费!H20 -> 90.023528 | J15: =运维费!I20 -> 90.023528 | K15: =运维费!J20 -> 90.023528 | ... O15: =运维费!N20 -> 98.779409
C19: - | D19: - | E19: - | F19: - | G19: - | H19: - | I19: - | J19: - | K19: - | L19: - | M19: - | N19: - | O19: -
C20: - | D20: - | E20: - | F20: - | G20: - | H20: - | I20: - | J20: - | K20: - | L20: - | M20: - | N20: - | O20: -
C21: - | D21: - | E21: - | F21: - | G21: - | H21: - | I21: - | J21: - | K21: - | L21: - | M21: - | N21: - | O21: -
C22: - | D22: - | E22: - | F22: - | G22: - | H22: - | I22: - | J22: - | K22: - | L22: - | M22: - | N22: - | O22: -
C23: - | D23: - | E23: - | F23: - | G23: - | H23: - | I23: - | J23: - | K23: - | L23: - | M23: - | N23: - | O23: -
C24: - | D24: - | E24: - | F24: - | G24: - | H24: - | I24: - | J24: - | K24: - | L24: - | M24: - | N24: - | O24: -
B25: 土地使用税及房产税（万元/年） | C25: - | D25: =输入参数!E36 -> 35.200018 | E25: =D25 -> 35.200018 | F25: =E25 -> 35.200018 | G25: =F25 -> 35.200018 | H25: =G25 -> 35.200018 | I25: =H25 -> 35.200018 | J25: =I25 -> 35.200018 | K25: =J25 -> 35.200018 | L25: =K25 -> 35.200018 | ... O25: =N25 -> 35.200018
B26: 应列未列的其他成本费用 | C26: - | D26: 0 | E26: 0 | F26: 0 | G26: 0 | H26: 0 | I26: 0 | J26: 0 | K26: 0 | L26: 0 | M26: 0 | N26: 0 | O26: 0
B27: 调度次数(次数) | C27: - | D27: =输入参数!E16 -> 255 | E27: =D27 -> 255 | F27: =E27 -> 255 | G27: =F27 -> 255 | H27: =G27 -> 255 | I27: =H27 -> 255 | J27: =I27 -> 255 | K27: =J27 -> 255 | L27: =K27 -> 255 | ... O27: =N27 -> 255
B28: 初始容量（万千瓦时） | C28: - | D28: =输入参数!E17*输入参数!E18 -> 20 | E28: =D28 -> 20 | F28: =E28 -> 20 | G28: =F28 -> 20 | H28: =G28 -> 20 | I28: =H28 -> 20 | J28: =I28 -> 20 | K28: =J28 -> 20 | L28: =K28 -> 20 | ... O28: =N28 -> 20
B29: 容量保持率 | C29: - | D29: 0.96393443 | E29: 0.94590164 | F29: 0.9295082 | G29: 0.91748634 | H29: 0.90382514 | I29: 0.89398907 | J29: 0.88196721 | K29: 0.87322404 | L29: 0.86120219 | M29: 0.85409836 | N29: 0.84371585 | O29: 0.83661202
B30: 充电电量（万千瓦时） | C30: - | D30: =D27*D28*D29 -> 4916.0656 | E30: =E27*E28*E29 -> 4824.0984 | F30: =F27*F28*F29 -> 4740.4918 | G30: =G27*G28*G29 -> 4679.1803 | H30: =H27*H28*H29 -> 4609.5082 | I30: =I27*I28*I29 -> 4559.3443 | J30: =J27*J28*J29 -> 4498.0328 | K30: =K27*K28*K29 -> 4453.4426 | ... O30: =O27*O28*O29 -> 4266.7213
B31: 充电电价（元/千瓦时） | C31: - | D31: =输入参数!E14 -> 0.2815 | E31: =D31 -> 0.2815 | F31: =E31 -> 0.2815 | G31: =F31 -> 0.2815 | H31: =G31 -> 0.2815 | I31: =H31 -> 0.2815 | J31: =I31 -> 0.2815 | K31: =J31 -> 0.2815 | L31: =K31 -> 0.2815 | ... O31: =N31 -> 0.2815
B32: 充电电费（万元） | C32: - | D32: =D30*D31 -> 1383.8725 | E32: =E30*E31 -> 1357.9837 | F32: =F30*F31 -> 1334.4484 | G32: =G30*G31 -> 1317.1893 | H32: =H30*H31 -> 1297.5766 | I32: =I30*I31 -> 1283.4554 | J32: =J30*J31 -> 1266.1962 | K32: =K30*K31 -> 1253.6441 | ... O32: =O30*O31 -> 1201.082

Sheet 分类折旧
A1: 固定资产折旧政策情况表
G2: 财管11表 | I2: 请根据项目情况填写设备费、安装费、主材费
A3: 编制单位：都城伟业集团有限公司 | D3: 2018年12月31日 | G3: 单位：元 | I3: 资产原值
A4: 固定资产分类 | B4: 行次 | C4: 折旧年限 | D4: 折旧方法 | E4: 折旧率（%） | F4: 净残值率（%） | G4: 备注 | I4: 设备费 | J4: 安装费 | K4: 主材费 | L4: 合计 | M4: 折旧
A5: 一、输电线路 | B5: 1 | I5: 0 | J5: 0 | K5: 0
A6: 1、架空输电线路 | B6: 2 | C6: 12 | D6: 年限平均法 | E6: 0.0317 | F6: 0.05 | I6: =静态总投!E5 -> 300 | J6: =静态总投!E10+静态总投!E11 -> 360 | K6: 0 | L6: =(I6+K6)/1.13+J6/1.09 -> 595.76196 | M6: =L6*(1-F6)/C6 -> 47.164488 | N6: 220kV送出工程
A7: 2、电缆输电线路 | B7: 3 | C7: 30 | D7: 年限平均法 | E7: 0.0317 | F7: 0.05 | I7: 0 | J7: 0 | K7: 0 | L7: =(I7+K7)/1.13+J7/1.09 -> 0 | M7: =L7*(1-F7)/C7 -> 0
A8: 二、变电设备 | B8: 4 | I8: 0 | J8: 0 | K8: 0
A9: 1、变压器 | B9: 5 | C9: 12 | D9: 年限平均法 | E9: 0.0528 | F9: 0.05 | I9: =静态总投!E4 -> 1800 | J9: 0 | K9: 0 | L9: =(I9+K9)/1.13+J9/1.09 -> 1592.9204 | M9: =L9*(1-F9)/C9 -> 126.10619 | N9: 升压站工程
A10: 2、换流设备 | B10: 6 | I10: 0 | J10: 0 | K10: 0
A11: （1）一次设备 | B11: 7 | C11: 10 | D11: 年限平均法 | E11: 0.0528 | F11: 0.05 | I11: 0 | J11: 0 | K11: 0 | L11: =(I11+K11)/1.13+J11/1.09 -> 0 | M11: =L11*(1-F11)/C11 -> 0
A12: （2）二次设备 | B12: 8 | C12: 10 | D12: 年限平均法 | E12: 0.0528 | F12: 0.05 | I12: 0 | J12: 0 | K12: 0 | L12: =(I12+K12)/1.13+J12/1.09 -> 0 | M12: =L12*(1-F12)/C12 -> 0
A13: （3）辅助设备 | B13: 9 | C13: 18 | D13: 年限平均法 | E13: 0.0528 | F13: 0.05 | I13: 0 | J13: 0 | K13: 0 | L13: =(I13+K13)/1.13+J13/1.09 -> 0 | M13: =L13*(1-F13)/C13 -> 0
A14: 3、电气一般设备 | B14: 10 | C14: 20 | D14: 年限平均法 | E14: 0.0528 | F14: 0.05 | I14: 0 | J14: 0 | K14: 0 | L14: =(I14+K14)/1.13+J14/1.09 -> 0 | M14: =L14*(1-F14)/C14 -> 0
A15: 4、电力电缆 | B15: 11 | I15: 0 | J15: 0 | K15: 0
A16: 三、配电线路及设备 | B16: 12 | I16: 0 | J16: 0 | K16: 0
A17: 1、配电线路 | B17: 13 | C17: 10 | D17: 年限平均法 | E17: 0.0792 | F17: 0.05 | I17: 0 | J17: 0 | K17: 0 | L17: =(I17+K17)/1.13+J17/1.09 -> 0 | M17: =L17*(1-F17)/C17 -> 0
A18: 2、配电设备 | B18: 14 | C18: 12 | D18: 年限平均法 | E18: 0.0792 | F18: 0.05 | I18: 0 | J18: 0 | K18: 0 | L18: =(I18+K18)/1.13+J18/1.09 -> 0 | M18: =L18*(1-F18)/C18 -> 0
A19: 3、电动汽车充换电设备 | B19: 15 | I19: 0 | J19: 0 | K19: 0
A20: 其中：电池 | B20: 16 | I20: 0 | J20: 0 | K20: 0
A21: 四、用电计量设备 | B21: 17 | C21: 7 | D21: 年限平均法 | E21: 0.1357 | F21: 0.05 | I21: 0 | J21: 0 | K21: 0 | L21: =(I21+K21)/1.13+J21/1.09 -> 0 | M21: =L21*(1-F21)/C21 -> 0
A22: 五、通讯线路及设备 | B22: 18 | I22: 0 | J22: 0 | K22: 0
A23: 1、通讯线路 | B23: 19 | C23: 10 | D23: 年限平均法 | E23: 0.095 | F23: 0.05 | I23: 0 | J23: 0 | K23: 0 | L23: =(I23+K23)/1.13+J23/1.09 -> 0 | M23: =L23*(1-F23)/C23 -> 0
A24: 2、通讯设备 | B24: 20 | C24: 10 | D24: 年限平均法 | E24: 0.095 | F24: 0.05 | I24: 0 | J24: 0 | K24: 0 | L24: =(I24+K24)/1.13+J24/1.09 -> 0 | M24: =L24*(1-F24)/C24 -> 0
A25: 六、自动化控制设备、信息设备及仪器仪表 | B25: 21 | I25: 0 | J25: 0 | K25: 0
A26: 1、继电保护及安全自动装置 | B26: 22 | C26: 8 | D26: 年限平均法 | E26: 0.1188 | F26: 0.05 | I26: 0 | J26: 0 | K26: 0 | L26: =(I26+K26)/1.13+J26/1.09 -> 0 | M26: =L26*(1-F26)/C26 -> 0
A27: 2、自动化系统及设备 | B27: 23 | C27: 8 | D27: 年限平均法 | E27: 0.1188 | F27: 0.05 | I27: 0 | J27: 0 | K27: 0 | L27: =(I27+K27)/1.13+J27/1.09 -> 0 | M27: =L27*(1-F27)/C27 -> 0
A28: 3、其他控制和保护设备 | B28: 24 | C28: 8 | D28: 年限平均法 | E28: 0.1188 | F28: 0.05 | I28: 0 | J28: 0 | K28: 0 | L28: =(I28+K28)/1.13+J28/1.09 -> 0 | M28: =L28*(1-F28)/C28 -> 0
A29: 4、信息系统设备 | B29: 25 | C29: 5 | D29: 年限平均法 | E29: 0.19 | F29: 0.05 | I29: 0 | J29: 0 | K29: 0 | L29: =(I29+K29)/1.13+J29/1.09 -> 0 | M29: =L29*(1-F29)/C29 -> 0
A30: 5、仪器仪表及测试设备 | B30: 26 | C30: 7 | D30: 年限平均法 | E30: 0.1375 | F30: 0.05 | I30: 0 | J30: 0 | K30: 0 | L30: =(I30+K30)/1.13+J30/1.09 -> 0 | M30: =L30*(1-F30)/C30 -> 0
A31: 七、发电及供热设备 | B31: 27 | I31: 0 | J31: 0 | K31: 0
A32: 1、输煤设备 | B32: 28 | I32: 0 | J32: 0 | K32: 0
A33: 2、煤粉设备 | B33: 29 | I33: 0 | J33: 0 | K33: 0
A34: 3、输油设备 | B34: 30 | I34: 0 | J34: 0 | K34: 0
A35: 4、锅炉设备 | B35: 31 | I35: 0 | J35: 0 | K35: 0
A36: 5、排污及疏水设备 | B36: 32 | I36: 0 | J36: 0 | K36: 0
A37: 6、烟气脱硫（硝）设备 | B37: 33 | I37: 0 | J37: 0 | K37: 0
A38: 7、除灰除尘设备 | B38: 34 | I38: 0 | J38: 0 | K38: 0
A39: 8、化学水处理设备 | B39: 35 | I39: 0 | J39: 0 | K39: 0
A40: 9、制氢设备 | B40: 36 | I40: 0 | J40: 0 | K40: 0
...

Sheet 参数汇总表
A1: 参数汇总表
A2: 序号 | B2: 项目 | C2: 单位 | D2: 数值
A3: 一 | B3: 工程概况
A4: 1 | B4: 装机容量 | C4: 万千瓦
A5: 2 | B5: 工期 | C5: 月
A6: 3 | B6: 项目运行期 | C6: 年
A7: 二 | B7: 投资类参数
A8: 1 | B8: 静态投资 | C8: 万元
A9: 2 | B9: 动态投资 | C9: 万元
A10: 3 | B10: 资本金比例 | C10: %
A11: 4 | B11: 可抵扣税金 | C11: 万元
A12: 5 | B12: 流动资金单位千瓦指标 | C12: 元/kW
A13: 三 | B13: 成本类参数
A14: 1 | B14: 还款期限 | C14: 年
A15: 2 | B15: 还本付息方式
A16: 3 | B16: 长期贷款利率 | C16: %
A17: 4 | B17: 流动资金贷款利率 | C17: %
A18: 5 | B18: 折旧年限 | C18: 年
A19: 6 | B19: 残值率 | C19: %
A20: 7 | B20: 维修费 | C20: 万元/年
A21: 8 | B21: 人工成本 | C21: 万元/年
A22: 8.1 | B22: 定员标准 | C22: 人
A23: 8.2 | B23: 人均年工资 | C23: 万元
A24: 8.3 | B24: 综合福利费 | C24: %
A25: 9 | B25: 保险费 | C25: %
A26: 10 | B26: 材料费 | C26: 元/kW/年
A27: 11 | B27: 其他费用
A28: 11.1 | B28: 其他费用1 | C28: 万元/年
A29: 11.2 | B29: 外购电费 | C29: 万元/年
A30: 11.3 | B30: 土地使用费 | C30: 万元/年
A31: 四 | B31: 收益类参数
A32: 1 | B32: 上网电价（含增值税） | C32: 元/kWh
A33: 2 | B33: 年等效利用小时数 | C33: h
A34: 3 | B34: 增值税税率 | C34: %
A35: 4 | B35: 所得税税率 | C35: %
A36: 5 | B36: 城市维护建设税 | C36: %
A37: 6 | B37: 教育费附加 | C37: %
A38: 7 | B38: 增值税即征即退50%
A39: 8 | B39: 所得税N免N减半
A40: 9 | B40: 补贴收入（含可抵扣税金） | C40: 万元

Sheet 静态总投
A1: 序号 | B1: 名称 | C1: 单位 | D1: 单价（元/Wh） | E1: 金额（万元） | F1: 备注
A2: 1 | B2: 设备费 | D2: =E2/20000 -> 0.555 | E2: =SUM(E3:E5) -> 11100 | F2: 设备费总计
A3: 1.1 | B3: 储能系统 | C3: 元/Wh | D3: 0.45 | E3: =D3*20000 -> 9000 | F3: 含电池抽检及验收费
A4: 1.2 | B4: 220kV升压站设备费 | C4: 元/Wh | D4: =E4/20000 -> 0.09 | E4: 1800
A5: 1.3 | B5: 220kV送出工程设备费 | C5: 元/Wh | D5: =E5/20000 -> 0.015 | E5: 300 | F5: 暂列
A6: 2 | B6: 建筑安装工程费 | C6: 元/Wh | D6: =E6/20000 -> 0.123 | E6: =SUM(E7:E11) -> 2460 | F6: 建安费总计
A7: 2.1 | B7: 储能+升压站建筑工程费（不含土建措施费） | C7: 元/Wh | D7: =E7/20000 -> 0.06 | E7: 1200
A8: 2.2 | B8: 土建整体措施 | C8: 元/Wh | D8: =E8/20000 -> 0.015 | E8: 300 | F8: 未知项目用地范围岩土情况，暂列
A9: 2.3 | B9: 储能+升压站安装费 | C9: 元/Wh | D9: =E9/20000 -> 0.03 | E9: 600
A10: 2.4 | B10: 220kV送出线路建安 | C10: 元/Wh | D10: =E10/20000 -> 0.01 | E10: 200
A11: 2.6 | B11: 对侧间隔扩建 | C11: 元/Wh | D11: =E11/20000 -> 0.008 | E11: 160 | F11: 拟接入500kV变电站的220kV侧，设备均新上。按不站外扩建考虑。
A12: 3 | B12: 前期专题 | D12: =E12/20000 -> 0.02885 | E12: =SUM(E13,E24,E34) -> 577
A13: 3.1 | B13: 本体项目前期费 | C13: 元/Wh | D13: =E13/20000 -> 0.01325 | E13: =SUM(E14:E23) -> 265 | F13: 按主要专题考虑，未知用地情况，部分特殊专题未计列。
A14: 3.1.1 | B14: 勘测定界 | C14: 元/Wh | D14: =E14/20000 -> 0.00115 | E14: 23
A15: 3.1.2 | B15: 环评 | C15: 元/Wh | D15: =E15/20000 -> 0.00075 | E15: 15
A16: 3.1.3 | B16: 水保 | C16: 元/Wh | D16: =E16/20000 -> 0.00075 | E16: 15
A17: 3.1.5 | B17: 地灾 | C17: 元/Wh | D17: =E17/20000 -> 0.000625 | E17: 12.5
A18: 3.1.6 | B18: 安评 | C18: 元/Wh | D18: =E18/20000 -> 0.000575 | E18: 11.5
A19: 3.1.8 | B19: 地震安全 | C19: 元/Wh | D19: =E19/20000 -> 0.0014 | E19: 28
A20: 3.1.9 | B20: 安全、卫生、职业健康等设计专篇 | C20: 元/Wh | D20: =E20/20000 -> 0.00075 | E20: 15
A21: 3.1.10 | B21: 规划选址 | C21: 元/Wh | D21: =E21/20000 -> 0.0005 | E21: 10
A22: 3.1.12 | B22: 本体可研（含第三方评审费10万元） | C22: 元/Wh | D22: =E22/20000 -> 0.002 | E22: 40
A23: 3.1.13 | B23: 接入系统、电能质量 | C23: 元/Wh | D23: =E23/20000 -> 0.00475 | E23: 95
A24: 3.2 | B24: 送出工程前期费 | C24: 元/Wh | D24: =E24/20000 -> 0.0066 | E24: =SUM(E25:E33) -> 132 | F24: 按主要专题考虑，未知用地情况，部分特殊专题未计列。
A25: 3.2.1 | B25: 社稳 | C25: 元/Wh | D25: =E25/20000 -> 0.0003 | E25: 6
A26: 3.2.2 | B26: 环评 | C26: 元/Wh | D26: =E26/20000 -> 0.00075 | E26: 15
A27: 3.2.3 | B27: 水保 | C27: 元/Wh | D27: =E27/20000 -> 0.00075 | E27: 15
A28: 3.2.4 | B28: 林地 | C28: 元/Wh | D28: =E28/20000 -> 0.0009 | E28: 18
A29: 3.2.5 | B29: 地灾 | C29: 元/Wh | D29: =E29/20000 -> 0.00075 | E29: 15
A30: 3.2.6 | B30: 安全评价 | C30: 元/Wh | D30: =E30/20000 -> 0.00055 | E30: 11
A31: 3.2.7 | B31: 文物调查 | C31: 元/Wh | D31: =E31/20000 -> 0.0005 | E31: 10
A32: 3.2.8 | B32: 送出可研（含国网经研院评审费12万元） | C32: 元/Wh | D32: =E32/20000 -> 0.0016 | E32: 32
A33: 3.2.9 | B33: 核准审请与报告 | C33: 元/Wh | D33: =E33/20000 -> 0.0005 | E33: 10
A34: 3.3 | B34: 勘察设计费及评审费 | C34: 元/Wh | D34: =E34/20000 -> 0.009 | E34: =SUM(E35:E37) -> 180 | F34: 包括本体和送出线路的勘察设计，含初步设计、施工图设计、竣工图设计。
A35: 3.3.1 | B35: 本体勘察设计费 | C35: 元/Wh | D35: =E35/20000 -> 0.005 | E35: 100
A36: 3.3.2 | B36: 线路勘察设计费（含国网间隔扩建） | C36: 元/Wh | D36: =E36/20000 -> 0.0025 | E36: 50
A37: 3.3.3 | B37: 设计文件评审+图审费 | C37: 元/Wh | D37: =E37/20000 -> 0.0015 | E37: 30 | F37: 初设10、施工图20
A38: 4 | B38: 项目其他费用 | C38: 元/Wh | D38: =E38/20000 -> 0.0196 | E38: =SUM(E39:E48) -> 392 | F38: 含项目建设管理费、设备材料监造费
A39: 4.1 | B39: 智慧工地 | C39: 元/Wh | D39: =E39/20000 -> 0.00075 | E39: 15 | F39: 依据当地政府要求配置
A40: 4.2 | B40: 本体环境监测及环境保护验收费 | C40: 元/Wh | D40: =E40/20000 -> 0.00075 | E40: 15
...

Sheet 财务指标及评价
B1: 财务指标汇总表
B2: 序号 | C2: 指标名称 | D2: 单位 | E2: 指标 | I2: 项目运营期12年年均营业收入 | J2: =IF(E11>10000,ROUND(E11/10000,2),ROUND(E11,0)) -> 3175 | K2: =IF(E11>10000,"亿元，","万元，") -> 万元，
B3: 1 | C3: 装机容量 | D3: 万千瓦 | E3: =输入参数!E17 -> 10 | I3: 年均利润总额 | J3: =IF(E13>10000,ROUND(E13/10000,2),ROUND(E13,0)) -> 230 | K3: =IF(E13>10000,"亿元，","万元，") -> 万元，
B4: 2 | C4: 年上网电量 | D4: 万千瓦时 | E4: =SUM('表2-利润与利润分配表'!F15:Q15)/12 -> 3717.2049 | I4: 年均净利润 | J4: =IF(E15>10000,ROUND(E15/10000,2),ROUND(E15,0)) -> 211 | K4: =IF(E15>10000,"亿元，","万元，") -> 万元，
B5: 2.1 | C5: 年利用小时数 | D5: 小时 | E5: =E4/E3 -> 371.72049 | I5: 全投资财务内部收益率 | J5: =ROUND(E17*100,2) -> 6.38 | K5: %，
B6: 3 | C6: 总投资 | D6: 万元 | E6: ='表1-投资计划与资金筹措表'!D6 -> 16036.414 | I6: 资本金财务内部收益率 | J6: =ROUND(E18*100,2) -> 17.97 | K6: %，
B7: 3.1 | C7: 固定资产 | D7: 万元 | E7: ='表2-利润与利润分配表'!D46 -> 14593.136 | I7: 投资回收期 | J7: =ROUND(E19,2) -> 9.2 | K7: 年。
B8: 3.2 | C8: 建设期利息 | D8: 万元 | E8: ='表1-投资计划与资金筹措表'!E8 -> 190.1551 | I8: 综上，项目收益情况 | J8: =IF(E18>6%,"较好","较差") -> 较好 | K8: ，
B9: 4 | C9: 上网电价（含增值税） | D9: 元/千瓦时 | E9: =输入参数!E13 -> 0.5868 | I9: =IF(E18>=7%,"满足","") -> 满足 | J9: =IF(E18>=9%,"优先投资",IF(E18>=6%,"允许投资。","不满足投资收益率标准要求。")) -> 优先投资 | K9: =IF(E18>=7%,"收益率标准。","") -> 收益率标准。
B10: 5 | C10: 发电营业收入总额 | D10: 万元 | E10: ='表2-利润与利润分配表'!D25 -> 38101.832
B11: 5.1 | C11: 年均营业收入 | D11: 万元 | E11: =E10/12 -> 3175.1527
B12: 6 | C12: 发电利润总额 | D12: 万元 | E12: ='表2-利润与利润分配表'!D34 -> 2760.759
B13: 6.1 | C13: 年均利润总额 | D13: 万元 | E13: =E12/12 -> 230.06325
B14: 7 | C14: 发电净利润 | D14: 万元 | E14: ='表2-利润与利润分配表'!D38 -> 2532.8435
B15: 7.1 | C15: 年均净利润 | D15: 万元 | E15: =E14/12 -> 211.07029
B16: 8 | C16: 财务内部收益率
B17: 8.1 | C17: 全投资内部收益率 | D17: % | E17: ='表3-项目现金流量表'!D24 -> 0.06376743
B18: 8.3 | C18: 资本金内部收益率 | D18: % | E18: ='表4-资本金现金流量表'!D22 -> 0.17967327
B19: 9 | C19: 投资回收期 | D19: 年 | E19: ='表3-项目现金流量表'!D29 -> 9.1963532
B21: =_xlfn.CONCAT(I2:K9) -> 项目运营期12年年均营业收入3175万元，年均利润总额230万元，年均净利润211万元，全投资财务内部收益率6.38%，资本金财务内部收益率17.97%，投资回收期9.2年。综上，项目收益情况较好，满足优先投资收益率标准。

Sheet 交易电价
B2: 排序 | C2: 省级电网 | D2: 燃煤发电标杆上网电价 | E2: 2019年交易导致的电价折减
E3: （不含两个细则考核）
B4: 1 | C4: 青海 | D4: 0.2277 | E4: 0.0641 | G4: =IF(输入参数!E11=C4,E4,0) -> 0
B5: 2 | C5: 新疆 | D5: 0.25 | E5: 0.1042 | G5: =IF(输入参数!E11=C5,E5,0) -> 0
B6: 2 | C6: 宁夏 | D6: 0.2595 | E6: 0.0284 | G6: =IF(输入参数!E11=C6,E6,0) -> 0
B7: 3 | C7: 蒙西 | D7: 0.2829 | E7: 0.0488 | G7: =IF(输入参数!E11=C7,E7,0) -> 0
B8: 4 | C8: 蒙东 | D8: 0.3035 | G8: =IF(输入参数!E11=C8,E8,0) -> 0
B9: 5 | C9: 甘肃 | D9: 0.3078 | E9: 0.1665 | G9: =IF(输入参数!E11=C9,E9,0) -> 0
B10: 6 | C10: 陕西(榆林) | D10: 0.3345 | E10: 0.0099 | G10: =IF(输入参数!E11=C10,E10,0) -> 0
B11: 7 | C11: 陕西 | D11: 0.3545 | E11: 0.015 | G11: =IF(输入参数!E11=C11,E11,0) -> 0
B12: 8 | C12: 冀北 | D12: 0.372 | E12: 0.0098 | G12: =IF(输入参数!E11=C12,E12,0) -> 0
B13: 10 | C13: 吉林 | D13: 0.3731 | E13: 0 | G13: =IF(输入参数!E11=C13,E13,0) -> 0
B14: 11 | C14: 黑龙江 | D14: 0.374 | E14: 0 | G14: =IF(输入参数!E11=C14,E14,0) -> 0
B15: 12 | C15: 辽宁 | D15: 0.3749 | E15: 0.014 | G15: =IF(输入参数!E11=C15,E15,0) -> 0
B16: 13 | C16: 安徽 | D16: 0.3844 | E16: 0 | G16: =IF(输入参数!E11=C16,E16,0) -> 0
B17: 14 | C17: 江苏 | D17: 0.391 | E17: 0.0055 | G17: =IF(输入参数!E11=C17,E17,0) -> 0
B18: 15 | C18: 福建 | D18: 0.3932 | E18: 0 | G18: =IF(输入参数!E11=C18,E18,0) -> 0
B19: 16 | C19: 山东 | D19: 0.3949 | E19: 0 | G19: =IF(输入参数!E11=C19,E19,0) -> 0
B20: 17 | C20: 浙江 | D20: 0.4153 | E20: 0 | G20: =IF(输入参数!E11=C20,E20,0) -> 0
B21: 18 | C21: 广东 | D21: 0.453 | E21: 0 | G21: =IF(输入参数!E11=C21,E21,0) -> 0
F22: 输出： | G22: =SUM(G4:G21) -> 0

Sheet 运维费
A2: 输出参数 | C2: 不同类型场站限额基准A | D2: 不同装机规模调整系数K1 | E2: 不同送出条件调整系数K3 | F2: 不同机型调整系数K4 | G2: 技改大修系数K5
A3: 计算结果 | C3: =18 -> 18 | D3: =IF(D4=2,1.25,IF(D4=5,1.05,IF(D4=10,1,IF(D4=15,0.98,IF(D4=20,0.95,IF(D4=30,0.93,IF(D4=40,0.9,IF(D4=50,0.85,0)))))))) -> 1 | E3: =IF(输入参数!E24="不包含送出线路及对侧间隔",1,IF(输入参数!E24="包含20km以内高压送出线路及对侧间隔",1.1,IF(输入参数!E24="包含40km以内高压送出线路及对侧间隔",1.15,IF(输入参数!E24="包含70km以内高压送出线路及对侧间隔",1.2,IF(输入参数!E24="包含100km以内高压送出线路及对侧间隔",1.3,0)))))*IF(输入参数!E25="330kV以下",1,IF(输入参数!E25="330kV及以上",1.1,0)) -> 1.1 | F3: 1 | G3: 1
A4: K2判断条件 | C4: =IF(输入参数!E17<=2,2,IF(输入参数!E17<=5,5,IF(输入参数!E17<=10,10,IF(输入参数!E17<=15,15,IF(输入参数!E17<=20,20,IF(输入参数!E17<=30,30,IF(输入参数!E17<=40,40,IF(输入参数!E17<50,50,50)))))))) -> 10 | D4: =IF(输入参数!E17/C4>0.85,C4,IF(输入参数!E17<=5,2,IF(输入参数!E17<=10,5,IF(输入参数!E17<=15,10,IF(输入参数!E17<=20,15,IF(输入参数!E17<=30,20,IF(输入参数!E17<=40,30,IF(输入参数!E17<50,40,0)))))))) -> 10
A6: 时间（年） | B6: 第1年 | C6: 第2年 | D6: 第3年 | E6: 第4年 | F6: 第5年 | G6: 第6年 | H6: 第7年 | I6: 第8年 | J6: 第9年 | K6: 第10年 | L6: 第11年 | M6: 第12年 | N6: 第13年
A7: 不同运营时长调整系数K2 | C7: 0.8 | D7: 1 | E7: 1 | F7: 1 | G7: 1.2 | H7: 1.2 | I7: 1.2 | J7: 1.2 | K7: 1.5 | L7: 1.5 | M7: 1.5 | N7: 1.5
A8: 场站生产费用限额（元/千瓦） | C8: =$C$3*($D$3*$E$3*$F$3*$G$3*C7) -> 15.84 | D8: =$C$3*($D$3*$E$3*$F$3*$G$3*D7) -> 19.8 | E8: =$C$3*($D$3*$E$3*$F$3*$G$3*E7) -> 19.8 | F8: =$C$3*($D$3*$E$3*$F$3*$G$3*F7) -> 19.8 | G8: =$C$3*($D$3*$E$3*$F$3*$G$3*G7) -> 23.76 | H8: =$C$3*($D$3*$E$3*$F$3*$G$3*H7) -> 23.76 | I8: =$C$3*($D$3*$E$3*$F$3*$G$3*I7) -> 23.76 | J8: =$C$3*($D$3*$E$3*$F$3*$G$3*J7) -> 23.76 | ... N8: =$C$3*($D$3*$E$3*$F$3*$G$3*N7) -> 29.7
A9: 运维费用限额（万元） | C9: =输入参数!$E$17*C8 -> 158.4 | D9: =输入参数!$E$17*D8 -> 198 | E9: =输入参数!$E$17*E8 -> 198 | F9: =输入参数!$E$17*F8 -> 198 | G9: =输入参数!$E$17*G8 -> 237.6 | H9: =输入参数!$E$17*H8 -> 237.6 | I9: =输入参数!$E$17*I8 -> 237.6 | J9: =输入参数!$E$17*J8 -> 237.6 | ... N9: =输入参数!$E$17*N8 -> 297
A10: 年均运维费用限额（万元）
A13: 固定资产价值 | C13: ='表1-投资计划与资金筹措表'!D6-输入参数!E22 -> 14593.136 | D13: =C13 -> 14593.136 | E13: =D13 -> 14593.136 | F13: =E13 -> 14593.136 | G13: =F13 -> 14593.136 | H13: =G13 -> 14593.136 | I13: =H13 -> 14593.136 | J13: =I13 -> 14593.136 | K13: =J13 -> 14593.136 | ... N13: =M13 -> 14593.136
A14: 维修费率 | C14: 0.002 | D14: 0.002 | E14: 0.002 | F14: 0.002 | G14: 0.002 | H14: 0.002 | I14: 0.002 | J14: 0.002 | K14: 0.002 | L14: 0.002 | M14: 0.002 | N14: 0.002
A15: 维修费限额 | C15: =C13*C14 -> 29.186273 | D15: =D13*D14 -> 29.186273 | E15: =E13*E14 -> 29.186273 | F15: =F13*F14 -> 29.186273 | G15: =G13*G14 -> 29.186273 | H15: =H13*H14 -> 29.186273 | I15: =I13*I14 -> 29.186273 | J15: =J13*J14 -> 29.186273 | ... N15: =N13*N14 -> 29.186273
A16: 不同运营时长调整系数 | C16: 0.8 | D16: 1 | E16: 1 | F16: 1 | G16: 1.2 | H16: 1.2 | I16: 1.2 | J16: 1.2 | K16: 1.5 | L16: 1.5 | M16: 1.5 | N16: 1.5
A17: 维修费用 | C17: =C15*C16 -> 23.349018 | D17: =D15*D16 -> 29.186273 | E17: =E15*E16 -> 29.186273 | F17: =F15*F16 -> 29.186273 | G17: =G15*G16 -> 35.023528 | H17: =H15*H16 -> 35.023528 | I17: =I15*I16 -> 35.023528 | J17: =J15*J16 -> 35.023528 | ... N17: =N15*N16 -> 43.779409
A18: 材料费 | C18: 40 | D18: 40 | E18: 40 | F18: 40 | G18: 40 | H18: 40 | I18: 40 | J18: 40 | K18: 40 | L18: 40 | M18: 40 | N18: 40
A19: 消防外委 | C19: 15 | D19: 15 | E19: 15 | F19: 15 | G19: 15 | H19: 15 | I19: 15 | J19: 15 | K19: 15 | L19: 15 | M19: 15 | N19: 15
A20: 维修及材料费用 | C20: =C17+C18+C19 -> 78.349018 | D20: =D17+D18+D19 -> 84.186273 | E20: =E17+E18+E19 -> 84.186273 | F20: =F17+F18+F19 -> 84.186273 | G20: =G17+G18+G19 -> 90.023528 | H20: =H17+H18+H19 -> 90.023528 | I20: =I17+I18+I19 -> 90.023528 | J20: =J17+J18+J19 -> 90.023528 | ... N20: =N17+N18+N19 -> 98.779409

Sheet 其他费用计算
A1: 项目公司成本费用统计表
A2: 费用类型 | B2: 成本项目 | C2: 甘肃 | D2: 新疆 | E2: 河北 | F2: 陕西 | G2: 内蒙古 | H2: 山东 | I2: 青海 | J2: 江苏 | K2: 总计
C3: 小计 | D3: 小计 | E3: 小计 | F3: 小计 | G3: 小计 | H3: 小计 | I3: 小计 | J3: 小计
A4: 纯场站费用 | B4: 购入电力费 | C4: 10745396 | D4: 3009124.8 | E4: 291597.37 | F4: 482316.65 | G4: 9266011.7 | H4: 96728.56 | I4: 1744252.7 | J4: 785362.07 | K4: 26420790
B5: 输电费 | C5: 0 | D5: 0 | E5: 0 | F5: 0 | G5: 0 | H5: 0 | I5: 0 | J5: 0 | K5: 0
B6: 折旧费 | C6: 1.4033853e+08 | D6: 69006927 | E6: 93202742 | F6: 51414320 | G6: 1.0130609e+08 | H6: 10111526 | I6: 2.5015498e+08 | J6: 1.2681565e+08 | K6: 8.4235076e+08
B7: 燃料费 | C7: 0 | D7: 0 | E7: 0 | F7: 0 | G7: 0 | H7: 0 | I7: 0 | J7: 0 | K7: 0
B8: 水费 | C8: 0 | D8: 0 | E8: 0 | F8: 0 | G8: 0 | H8: 0 | I8: 12000 | J8: 0 | K8: 12000
B9: 材料费及修理费 | C9: 10885193 | D9: 1892392.1 | E9: 1302288.6 | F9: 3517404.8 | G9: 4289776 | H9: 888945.99 | I9: 1201082.9 | J9: 133167.23 | K9: 24110250
B10: 委托运行维护费 | C10: 2624400.2 | D10: 2653567.5 | E10: 4933154.6 | F10: 0 | G10: 2737608.4 | H10: 0 | I10: 6931655.3 | J10: 6153302.4 | K10: 26033688
B11: 财产保险费 | C11: 1969952.8 | D11: 1206677.1 | E11: 835791.32 | F11: 650972.18 | G11: 1225017.9 | H11: 50803.44 | I11: 2502966.4 | J11: 4683191.8 | K11: 13125373
B12: 电力设施保护费 | C12: 0 | D12: 0 | E12: 0 | F12: 0 | G12: 0 | H12: 0 | I12: 0 | J12: 0 | K12: 0
B13: 安全费 | C13: 436916.4 | D13: 207803.07 | E13: 66033.33 | F13: 68031.55 | G13: 249170.14 | H13: 38937.09 | I13: 579252.09 | J13: 1039486.6 | K13: 2685630.2
B14: 长期待摊费用摊销 | C14: 1535809.6 | D14: 0 | E14: 116616.69 | F14: 526728.08 | G14: 554108.34 | H14: 2112876.5 | I14: 0 | J14: 709489.2 | K14: 5555628.4
B15: 无形资产摊销 | C15: 415882.1 | D15: 864865.84 | E15: 173047.09 | F15: 288847.35 | G15: 372066.12 | H15: 425933.77 | I15: 153750.96 | J15: 117161.14 | K15: 2811554.4
B16: 存货盘亏和毁损 | C16: 0 | D16: 0 | E16: 0 | F16: 0 | G16: 0 | H16: 0 | I16: 0 | J16: 0 | K16: 0
... B20: 知识产权维护费 | C20: 0 | D20: 0 | E20: 0 | F20: 0 | G20: 0 | H20: 0 | I20: 0 | J20: 0 | K20: 0
A21: 小计 | C21: =SUM(C4:C20) -> 1.6895208e+08 | D21: =SUM(D4:D20) -> 78841357 | E21: =SUM(E4:E20) -> 1.0092127e+08 | F21: =SUM(F4:F20) -> 56948620 | G21: =SUM(G4:G20) -> 1.2003464e+08 | H21: =SUM(H4:H20) -> 13725752 | I21: =SUM(I4:I20) -> 2.6327994e+08 | J21: =SUM(J4:J20) -> 1.4051228e+08 | K21: =SUM(K4:K20) -> 9.4321594e+08
A22: 区域公司 人工成本 | B22: 工资 | C22: 25129400 | D22: 19984300 | E22: 20217745 | F22: 16618000 | G22: 26597717 | H22: 12308500 | I22: 43672100 | J22: 22378400 | K22: 1.7826803e+08
B23: 社会保险费 | C23: 7660571.9 | D23: 5555319.5 | E23: 3928460.7 | F23: 3457912.8 | G23: 6814138 | H23: 2775998.2 | I23: 11272242 | J23: 4700380.3 | K23: 43297816
B24: 住房公积金 | C24: 2065906.7 | D24: 1619093.4 | E24: 1553759.7 | F24: 1301612.1 | G24: 2002565.5 | H24: 848523.94 | I24: 3839542.9 | J24: 1876665.4 | K24: 14288249
B25: 职工福利费 | C25: 2077416.8 | D25: 1589158 | E25: 2016407.1 | F25: 1374478.2 | G25: 1992452.1 | H25: 782361.75 | I25: 2915827.5 | J25: 1402143.7 | K25: 14054621
B26: 工资附加 | C26: 980587.14 | D26: 399685.99 | E26: 846565.52 | F26: 528636.21 | G26: 1082172.8 | H26: 362131.73 | I26: 1324978.5 | J26: 840816.9 | K26: 5911956.1
B27: 劳务派遣费 | C27: 784889.13 | D27: 0 | E27: 302660.26 | F27: 673859.25 | G27: 1552505.2 | H27: 0 | I27: 0 | J27: 636155.5 | K27: 3949772.3
B28: 临时用工薪酬 | C28: 0 | D28: 0 | E28: 0 | F28: 0 | G28: 0 | H28: 0 | I28: 0 | J28: 0 | K28: 0
B29: 辞退福利 | C29: 0 | D29: 0 | E29: 0 | F29: 0 | G29: 0 | H29: 0 | I29: 0 | J29: 0 | K29: 0
B30: 劳动保护费 | C30: 117309.11 | D30: 187348.33 | E30: 280153.92 | F30: 136469.2 | G30: 307351.28 | H30: 88977.85 | I30: 233333.23 | J30: 165817.21 | K30: 1516760.1
A31: 小计 | C31: 38816081 | D31: =SUM(D22:D30) -> 29334905 | E31: =SUM(E22:E30) -> 29145752 | F31: =SUM(F22:F30) -> 24090968 | G31: =SUM(G22:G30) -> 40348902 | H31: =SUM(H22:H30) -> 17166493 | I31: =SUM(I22:I30) -> 63258024 | J31: =SUM(J22:J30) -> 32000379 | K31: =SUM(K22:K30) -> 2.612872e+08
A32: 各场站人工成本 | C32: 13655713 | D32: 10656388 | E32: 16737579 | F32: 7638208 | G32: 16672998 | H32: 3491429 | I32: 39410663 | J32: 7428258 | K32: =SUM(K23:K31) -> 3.4430638e+08
A33: 下沉人工成本 | C33: =C31-C32 -> 25160368 | D33: =D31-D32 -> 18678517 | E33: =E31-E32 -> 12408173 | F33: =F31-F32 -> 16452760 | G33: =G31-G32 -> 23675904 | H33: =H31-H32 -> 13675064 | I33: =I31-I32 -> 23847361 | J33: =J31-J32 -> 24572121 | K33: =SUM(K24:K32) -> 6.4531494e+08
A34: 管理性费用下沉 | B34: 低值易耗品摊销 | C34: 90920.12 | D34: 26036.01 | E34: 251281.55 | F34: 291868.04 | G34: 130175.65 | H34: 27570.01 | I34: 279097.45 | J34: 89258.89 | K34: 1186207.7
B35: 研究开发费 | C35: 0 | D35: 0 | E35: 886792.5 | F35: 0 | G35: 0 | H35: 0 | I35: 0 | J35: 0 | K35: 886792.5
B36: 办公费 | C36: 391452.8 | D36: 288134.99 | E36: 258061.69 | F36: 328968.05 | G36: 323911.95 | H36: 97357.16 | I36: 376855.87 | J36: 225729.84 | K36: 2290472.4
B37: 差旅费 | C37: 1546726.1 | D37: 1159389.3 | E37: 957258.07 | F37: 944046.24 | G37: 1469897.7 | H37: 649412.21 | I37: 1918065 | J37: 1678644.1 | K37: 10323439
B38: 会议费 | C38: 17106.91 | D38: 0 | E38: 12409.33 | F38: 6796.12 | G38: 13592.24 | H38: 9348.54 | I38: 25586.51 | J38: 39021.34 | K38: 123860.99
B39: 业务招待费 | C39: 0 | D39: 0 | E39: 0 | F39: 0 | G39: 0 | H39: 0 | I39: 0 | J39: 0 | K39: 0
B40: 公务用车辆使用费 | C40: 0 | D40: 66652.23 | E40: 0 | F40: 0 | G40: 0 | H40: 0 | I40: 0 | J40: 0 | K40: 66652.23
B41: 生产用车辆使用费 | C41: 681236.47 | D41: 289413.55 | E41: 487603.03 | F41: 231588.76 | G41: 592323.82 | H41: 164542.84 | I41: 521489.19 | J41: 195501.48 | K41: 3163699.1
B42: 物业管理费 | C42: 64588.01 | D42: 61971.72 | E42: 1022628.8 | F42: 254595.75 | G42: 102523.07 | H42: 184511.2 | I42: 0 | J42: 641116.11 | K42: 2331934.7
B43: 管理用房屋维修费 | C43: 0 | D43: 0 | E43: 0 | F43: 0 | G43: 0 | H43: 0 | I43: 0 | J43: 0 | K43: 0
...

Sheet 人工成本
B2: 序号 | C2: 单位名称 | D2: 场站人数 | E2: 场站职工人工成本总额（万元）
E3: 合计 | F3: 人均
B4: 1 | C4: 甘肃公司 | D4: 40 | E4: 1366 | F4: 34
B5: 2 | C5: 新疆公司 | D5: 30 | E5: 1066 | F5: 36
B6: 3 | C6: 河北公司 | D6: 64 | E6: 1674 | F6: 26
B7: 4 | C7: 陕西公司 | D7: 24 | E7: 764 | F7: 32
B8: 5 | C8: 内蒙公司 | D8: 49 | E8: 1667 | F8: 34
B9: 6 | C9: 山东公司 | D9: 10 | E9: 349 | F9: 35
B10: 7 | C10: 青海公司 | D10: 111 | E10: 3941 | F10: 36
B11: 8 | C11: 江苏公司 | D11: 23 | E11: 743 | F11: 32
E12: 公司判断 | F12: =其他费用计算!D73 -> 0 | G12: 输出 | H12: 35

Sheet 表1-投资计划与资金筹措表
B2: 投资计划与资金筹措表
B4: 序号 | C4: 项目 | D4: 合计 | E4: 建设期 | F4: 运营期
E5: 第1年 | F5: 第2年 | G5: 第3年 | H5: 第4年 | I5: 第5年 | J5: 第6年 | K5: 第7年 | L5: 第8年 | M5: 第9年 | N5: 第10年 | O5: 第11年 | P5: 第12年 | Q5: 第13年
B6: 1 | C6: 总投资规模（动态） | D6: =D7+D8 -> 16036.414 | E6: =E7+E8 -> 16036.414
B7: 2 | C7: 建设投资（静态） | D7: =SUM(E7) -> 15846.259 | E7: =输入参数!E3 -> 15846.259
B8: 3 | C8: 建设期利息 | D8: =SUM(E8) -> 190.1551 | E8: =E7*0.8*0.03/2 -> 190.1551
B9: 4 | C9: 资金筹措 | D9: =D7+D8 -> 16036.414 | E9: =E7+E8 -> 16036.414
B10: 5 | C10: 资本金 | D10: =E10+P10 -> 3207.2827 | E10: =E6*0.2 -> 3207.2827
B11: 6 | C11: 长期借款 | D11: =E11+P11 -> 12829.131 | E11: =D6*0.8 -> 12829.131
B12: 7 | C12: 长期借款本金 | D12: =SUM(E12:Q12) -> 12677.007 | E12: =E7*0.8 -> 12677.007
B13: 8 | C13: 偿还长期借款本金 | D13: =SUM(E13:Q13) -> 12829.131 | F13: ='表5-借款还本付息表'!F11 -> 1119.0916 | G13: ='表5-借款还本付息表'!G11 -> 1152.6643 | H13: ='表5-借款还本付息表'!H11 -> 1187.2443 | I13: ='表5-借款还本付息表'!I11 -> 1222.8616 | J13: ='表5-借款还本付息表'!J11 -> 1259.5474 | K13: ='表5-借款还本付息表'!K11 -> 1297.3339 | L13: ='表5-借款还本付息表'!L11 -> 1336.2539 | M13: ='表5-借款还本付息表'!M11 -> 1376.3415 | ... Q13: ='表5-借款还本付息表'!Q11 -> -3.9344741e-13
B14: 9 | C14: 偿还长期借款利息 | D14: =SUM(E14:Q14) -> 2210.5243 | F14: ='表5-借款还本付息表'!F13 -> 384.87393 | G14: ='表5-借款还本付息表'!G13 -> 351.30118 | H14: ='表5-借款还本付息表'!H13 -> 316.72125 | I14: ='表5-借款还本付息表'!I13 -> 281.10392 | J14: ='表5-借款还本付息表'!J13 -> 244.41807 | K14: ='表5-借款还本付息表'!K13 -> 206.63165 | L14: ='表5-借款还本付息表'!L13 -> 167.71164 | M14: ='表5-借款还本付息表'!M13 -> 127.62402 | ... Q14: ='表5-借款还本付息表'!Q13 -> 3.9344741e-13

Sheet 表2-利润与利润分配表
B2: 利润与利润分配表
B4: 序号 | C4: 项目 | D4: 合计 | E4: 建设期 | F4: 运营期
B5: - | E5: 第1年 | F5: 第2年 | G5: 第3年 | H5: 第4年 | I5: 第5年 | J5: 第6年 | K5: 第7年 | L5: 第8年 | M5: 第9年 | N5: 第10年 | O5: 第11年 | P5: 第12年 | Q5: 第13年
C6: 调度次数 | F6: =手动输入参数表!D27 -> 255 | G6: =F6 -> 255 | H6: =G6 -> 255 | I6: =H6 -> 255 | J6: =I6 -> 255 | K6: =J6 -> 255 | L6: =K6 -> 255 | M6: =L6 -> 255 | N6: =M6 -> 255 | ... Q6: =P6 -> 255
C7: 电化学装机容量（万千瓦) | D7: =输入参数!E17 -> 10 | F7: =D7 -> 10 | G7: =F7 -> 10 | H7: =G7 -> 10 | I7: =H7 -> 10 | J7: =I7 -> 10 | K7: =J7 -> 10 | L7: =K7 -> 10 | M7: =L7 -> 10 | N7: =M7 -> 10 | ... Q7: =P7 -> 10
C8: 储能时长（小时） | F8: =输入参数!E18 -> 2 | G8: =F8 -> 2 | H8: =G8 -> 2 | I8: =H8 -> 2 | J8: =I8 -> 2 | K8: =J8 -> 2 | L8: =K8 -> 2 | M8: =L8 -> 2 | N8: =M8 -> 2 | ... Q8: =P8 -> 2
C9: 储能容量保持率 | F9: 0.96393443 | G9: 0.94590164 | H9: 0.9295082 | I9: 0.91748634 | J9: 0.90382514 | K9: 0.89398907 | L9: 0.88196721 | M9: 0.87322404 | N9: 0.86120219 | O9: 0.85409836 | P9: 0.84371585 | Q9: 0.83661202
C10: 转换效率 | F10: 0.86 | G10: 0.86 | H10: 0.86 | I10: 0.86 | J10: 0.86 | K10: 0.86 | L10: 0.86 | M10: 0.86 | N10: 0.86 | O10: 0.86 | P10: 0.86 | Q10: 0.86
C11: 放电率 | F11: 0.95 | G11: 0.95 | H11: 0.95 | I11: 0.95 | J11: 0.95 | K11: 0.95 | L11: 0.95 | M11: 0.95 | N11: 0.95 | O11: 0.95 | P11: 0.95 | Q11: 0.95
C12: 上网小时数（小时） | F12: =F15/10 -> 401.64256 | G12: =G15/10 -> 394.12884 | H12: =H15/10 -> 387.29818 | I12: =I15/10 -> 382.28903 | J12: =J15/10 -> 376.59682 | K12: =K15/10 -> 372.49843 | L12: =L15/10 -> 367.48928 | M12: =M15/10 -> 363.84626 | ... Q12: =Q15/10 -> 348.59113
C13: 不参与交易的上网小时数 | D13: =输入参数!E7 -> 0
C14: 参与交易的上网小时数
B15: - | C15: 上网电量 | D15: =SUM(E15:Q15) -> 44606.459 | F15: =F6*F7*F8*F9*F10*F11 -> 4016.4256 | G15: =G6*G7*G8*G9*G10*G11 -> 3941.2884 | H15: =H6*H7*H8*H9*H10*H11 -> 3872.9818 | I15: =I6*I7*I8*I9*I10*I11 -> 3822.8903 | J15: =J6*J7*J8*J9*J10*J11 -> 3765.9682 | K15: =K6*K7*K8*K9*K10*K11 -> 3724.9843 | L15: =L6*L7*L8*L9*L10*L11 -> 3674.8928 | M15: =M6*M7*M8*M9*M10*M11 -> 3638.4626 | ... Q15: =Q6*Q7*Q8*Q9*Q10*Q11 -> 3485.9113 | R15: =D15/12 -> 3717.2049
C16: 等效调度次数 | F16: =F15/(F8*F7) -> 200.82128 | G16: =G15/(G8*G7) -> 197.06442 | H16: =H15/(H8*H7) -> 193.64909 | I16: =I15/(I8*I7) -> 191.14452 | J16: =J15/(J8*J7) -> 188.29841 | K16: =K15/(K8*K7) -> 186.24921 | L16: =L15/(L8*L7) -> 183.74464 | M16: =M15/(M8*M7) -> 181.92313 | ... Q16: =Q15/(Q8*Q7) -> 174.29557
C17: 放电交易电价（不含税） | D17: =D18/1.13 -> 0.51929204 | F17: =D17 -> 0.51929204 | G17: =F17 -> 0.51929204 | H17: =F17 -> 0.51929204 | I17: =H17 -> 0.51929204 | J17: =H17 -> 0.51929204 | K17: =J17 -> 0.51929204 | L17: =J17 -> 0.51929204 | M17: =L17 -> 0.51929204 | N17: =L17 -> 0.51929204 | O17: =N17 -> 0.51929204 | P17: =N17 -> 0.51929204 | Q17: =P17 -> 0.51929204
C18: 放电交易电价（含税） | D18: =输入参数!E13 -> 0.5868 | F18: =D18 -> 0.5868 | G18: =F18 -> 0.5868 | H18: =F18 -> 0.5868 | I18: =H18 -> 0.5868 | J18: =H18 -> 0.5868 | K18: =J18 -> 0.5868 | L18: =J18 -> 0.5868 | M18: =L18 -> 0.5868 | N18: =L18 -> 0.5868 | O18: =N18 -> 0.5868 | P18: =O18 -> 0.5868 | Q18: =P18 -> 0.5868 | R18: =R15*Q18 -> 2181.2558
C19: 补贴电价合计（不含税）（万元） | F19: =F20/1.13 -> 884.95575 | G19: =F19 -> 884.95575 | H19: =F19 -> 884.95575 | I19: =H19 -> 884.95575 | J19: =H19 -> 884.95575 | K19: =J19 -> 884.95575 | L19: =J19 -> 884.95575 | M19: =L19 -> 884.95575 | N19: =L19 -> 884.95575 | O19: =N19 -> 884.95575 | P19: =O19 -> 884.95575 | Q19: =P19 -> 884.95575
C20: 补贴电价合计（含税）（万元） | F20: 1000 | G20: =F20 -> 1000 | H20: =G20 -> 1000 | I20: =H20 -> 1000 | J20: =I20 -> 1000 | K20: =J20 -> 1000 | L20: =K20 -> 1000 | M20: =L20 -> 1000 | N20: =M20 -> 1000 | O20: 1000 | P20: 1000 | Q20: 1000
C21: 调峰调频收入（万元） | F21: =200*400*30/10000 -> 240 | G21: =F21 -> 240 | H21: =G21 -> 240 | I21: =H21 -> 240 | J21: =I21 -> 240 | K21: =J21 -> 240 | L21: =K21 -> 240 | M21: =L21 -> 240 | N21: =M21 -> 240 | ... Q21: =P21 -> 240
C22: 政府补贴收入（万元） | F22: 2000
B23: 1 | C23: 销售收入（含税） | D23: =SUM(E23:Q23) -> 43055.07 | F23: =F15*F18+F20+F21+F22 -> 5596.8385 | G23: =G15*G18+G20+G21 -> 3552.748 | H23: =H15*H18+H20+H21 -> 3512.6657 | I23: =I15*I18+I20+I21 -> 3483.272 | J23: =J15*J18+J20+J21 -> 3449.8701 | K23: =K15*K18+K20+K21 -> 3425.8208 | L23: =L15*L18+L20+L21 -> 3396.4271 | M23: =M15*M18+M20+M21 -> 3375.0499 | N23: =N15*N18+N20+N21 -> 3345.6562 | ... Q23: =Q15*Q18+Q20+Q21 -> 3285.5328
C24: 两个细则考核 | D24: =SUM(E24:Q24) -> 0 | F24: 0 | G24: =F24 -> 0 | H24: =G24 -> 0 | I24: =H24 -> 0 | J24: =I24 -> 0 | K24: =J24 -> 0 | L24: =K24 -> 0 | M24: =L24 -> 0 | N24: =M24 -> 0 | ... Q24: =P24 -> 0
B25: 2 | C25: 营业收入（不含税） | D25: =SUM(E25:Q25) -> 38101.832 | F25: =(F15*F18+F21+F20+F22)/1.13 -> 4952.9544 | G25: =G23/1.13 -> 3144.0248 | H25: =H23/1.13 -> 3108.5537 | I25: =I23/1.13 -> 3082.5416 | J25: =J23/1.13 -> 3052.9824 | K25: =K23/1.13 -> 3031.6998 | L25: =L23/1.13 -> 3005.6877 | M25: =M23/1.13 -> 2986.7698 | N25: =N23/1.13 -> 2960.7577 | ... Q25: =Q23/1.13 -> 2907.5511 | R25: =D25/12 -> 3175.1527
B26: 3 | C26: 增值税
C27: 当期增值税销项税 | D27: =SUM(E27:Q27) -> 4953.2381 | E27: 0 | F27: =F23-F25 -> 643.88408 | G27: =G23-G25 -> 408.72322 | H27: =H23-H25 -> 404.11199 | I27: =I23-I25 -> 400.73041 | J27: =J23-J25 -> 396.88771 | K27: =K23-K25 -> 394.12097 | L27: =L23-L25 -> 390.7394 | M27: =M23-M25 -> 388.28007 | ... Q27: =Q23-Q25 -> 377.98164
C28: 可抵扣增值进项税 | D28: =SUM(E28:Q28) -> 2742.4714 | F28: =IF(F27>F45,IF(F45<=0,0,F45),F27) -> 643.88408 | G28: =IF(G27>G45,IF(G45<=0,0,G45),G27) -> 408.72322 | H28: =IF(H27>H45,IF(H45<=0,0,H45),H27) -> 390.66993 | I28: ='表6-运营成本费用表'!I15/1.13*0.13 -> 151.53505 | J28: ='表6-运营成本费用表'!J15/1.13*0.13 -> 149.27872 | K28: ='表6-运营成本费用表'!K15/1.13*0.13 -> 147.65416 | L28: ='表6-运营成本费用表'!L15/1.13*0.13 -> 145.66859 | M28: ='表6-运营成本费用表'!M15/1.13*0.13 -> 144.22454 | N28: ='表6-运营成本费用表'!N15/1.13*0.13 -> 142.23897 | O28: ='表6-运营成本费用表'!O15/1.13*0.13 -> 141.06568 | P28: ='表6-运营成本费用表'!P15/1.13*0.13 -> 139.35087 | Q28: ='表6-运营成本费用表'!Q15/1.13*0.13 -> 138.17758
C29: 当期缴纳增值税 | D29: =SUM(E29:Q29) -> 2210.7667 | E29: 0 | F29: =F27-F28 -> 0 | G29: =G27-G28 -> 0 | H29: =H27-H28 -> 13.442053 | I29: =I27-I28 -> 249.19536 | J29: =J27-J28 -> 247.609 | K29: =K27-K28 -> 246.46681 | L29: =L27-L28 -> 245.07081 | M29: =M27-M28 -> 244.05553 | ... Q29: =Q27-Q28 -> 239.80406
B30: 4 | C30: 销售税金及附加 | D30: =SUM(E30:Q30) -> 265.29201 | F30: =F29*F31 -> 0 | G30: =G29*G31 -> 0 | H30: =H29*H31 -> 1.6130464 | I30: =I29*I31 -> 29.903444 | J30: =J29*J31 -> 29.71308 | K30: =K29*K31 -> 29.576017 | L30: =L29*L31 -> 29.408497 | M30: =M29*M31 -> 29.286664 | ... Q30: =Q29*Q31 -> 28.776488
C31: 综合税率： | D31: =输入参数!E34 -> 0.12 | F31: =D31 -> 0.12 | G31: =F31 -> 0.12 | H31: =G31 -> 0.12 | I31: =H31 -> 0.12 | J31: =I31 -> 0.12 | K31: =J31 -> 0.12 | L31: =K31 -> 0.12 | M31: =L31 -> 0.12 | N31: =M31 -> 0.12 | ... Q31: =P31 -> 0.12
B32: 5 | C32: 发电成本费用 | D32: =SUM(E32:Q32) -> 35075.781 | F32: ='表6-运营成本费用表'!F16 -> 3187.6389 | G32: ='表6-运营成本费用表'!G16 -> 3138.4557 | H32: ='表6-运营成本费用表'!H16 -> 3084.9101 | I32: ='表6-运营成本费用表'!I16 -> 3036.7352 | J32: ='表6-运营成本费用表'!J16 -> 2991.1117 | K32: ='表6-运营成本费用表'!K16 -> 2944.1819 | L32: ='表6-运营成本费用表'!L16 -> 2893.1246 | M32: ='表6-运营成本费用表'!M16 -> 2845.7551 | ... Q32: ='表6-运营成本费用表'!Q16 -> 2696.9781
C33: 其中 利息费用： | D33: =SUM(E33:Q33) -> 2210.5243 | F33: ='表5-借款还本付息表'!F19 -> 384.87393 | G33: ='表5-借款还本付息表'!G19 -> 351.30118 | H33: ='表5-借款还本付息表'!H19 -> 316.72125 | I33: ='表5-借款还本付息表'!I19 -> 281.10392 | J33: ='表5-借款还本付息表'!J19 -> 244.41807 | K33: ='表5-借款还本付息表'!K19 -> 206.63165 | L33: ='表5-借款还本付息表'!L19 -> 167.71164 | M33: ='表5-借款还本付息表'!M19 -> 127.62402 | ... Q33: ='表5-借款还本付息表'!Q19 -> 3.9344741e-13
B34: 6 | C34: 利润总额 | D34: =SUM(E34:Q34) -> 2760.759 | F34: =F25-F32-F30 -> 1765.3156 | G34: =G25-G32-G30 -> 5.5690712 | H34: =H25-H32-H30 -> 22.030635 | I34: =I25-I32-I30 -> 15.90295 | J34: =J25-J32-J30 -> 32.157665 | K34: =K25-K32-K30 -> 57.941903 | L34: =L25-L32-L30 -> 83.154625 | M34: =M25-M32-M30 -> 111.72808 | ... Q34: =Q25-Q32-Q30 -> 181.79654 | R34: =D34/12 -> 230.06325
B35: 7 | C35: 弥补以前年度亏损 | D35: =SUM(E35:Q35) -> 0 | F35: 0 | G35: 0 | H35: 0 | I35: 0 | J35: 0 | K35: 0 | L35: 0 | M35: 0 | N35: 0 | O35: 0 | P35: 0 | Q35: 0
B36: 8 | C36: 应纳税所得额 | D36: =SUM(E36:Q36) -> 2760.759 | F36: =IF(F34<0,0,-F35+F34) -> 1765.3156 | G36: =IF(G34<0,0,-G35+G34) -> 5.5690712 | H36: =IF(H34<0,0,-H35+H34) -> 22.030635 | I36: =IF(I34<0,0,-I35+I34) -> 15.90295 | J36: =IF(J34<0,0,-J35+J34) -> 32.157665 | K36: =IF(K34<0,0,-K35+K34) -> 57.941903 | L36: =IF(L34<0,0,-L35+L34) -> 83.154625 | M36: =IF(M34<0,0,-M35+M34) -> 111.72808 | ... Q36: =IF(Q34<0,0,-Q35+Q34) -> 181.79654
B37: 9 | C37: 所得税 | D37: =SUM(E37:Q37) -> 227.91547 | F37: 0 | G37: 0 | H37: 0 | I37: =I36*15%*0.5 -> 1.1927212 | J37: =J36*25%*0.5 -> 4.0197081 | K37: =K36*25%*0.5 -> 7.2427378 | L37: =L36*25% -> 20.788656 | M37: =M36*25% -> 27.932019 | N37: =N36*25% -> 32.563528 | O37: =O36*25% -> 40.532446 | P37: =P36*25% -> 48.194522 | Q37: =Q36*25% -> 45.449134
B38: 10 | C38: 净利润 | D38: =SUM(E38:Q38) -> 2532.8435 | F38: =F34-F37 -> 1765.3156 | G38: =G34-G37 -> 5.5690712 | H38: =H34-H37 -> 22.030635 | I38: =I34-I37 -> 14.710229 | J38: =J34-J37 -> 28.137957 | K38: =K34-K37 -> 50.699165 | L38: =L34-L37 -> 62.365969 | M38: =M34-M37 -> 83.796058 | ... Q38: =Q34-Q37 -> 136.3474 | R38: =D38/12 -> 211.07029
B39: 11 | C39: 期初未分配利润 | D39: =SUM(E39:Q39) -> 19457.23 | F39: =E41 -> 0 | G39: =F41 -> 1588.784 | H39: =G41 -> 1593.7962 | I39: =H41 -> 1613.6237 | J39: =I41 -> 1626.8629 | K39: =J41 -> 1652.1871 | L39: =K41 -> 1697.8164 | M39: =L41 -> 1753.9457 | ... Q39: =P41 -> 2156.8465
B40: 12 | C40: 提取法定盈余公积金 | D40: =SUM(E40:Q40) -> 253.28435 | F40: =IF(F38<0,0,F38*0.1) -> 176.53156 | G40: =IF(G38<0,0,G38*0.1) -> 0.55690712 | H40: =IF(H38<0,0,H38*0.1) -> 2.2030635 | I40: =IF(I38<0,0,I38*0.1) -> 1.4710229 | J40: =IF(J38<0,0,J38*0.1) -> 2.8137957 | K40: =IF(K38<0,0,K38*0.1) -> 5.0699165 | L40: =IF(L38<0,0,L38*0.1) -> 6.2365969 | M40: =IF(M38<0,0,M38*0.1) -> 8.3796058 | ... Q40: =IF(Q38<0,0,Q38*0.1) -> 13.63474
B41: 13 | C41: 期末未分配利润 | D41: =SUM(E41:Q41) -> 21736.789 | E41: 0 | F41: =F38+F39-F40 -> 1588.784 | G41: =G38+G39-G40 -> 1593.7962 | H41: =H38+H39-H40 -> 1613.6237 | I41: =I38+I39-I40 -> 1626.8629 | J41: =J38+J39-J40 -> 1652.1871 | K41: =K38+K39-K40 -> 1697.8164 | L41: =L38+L39-L40 -> 1753.9457 | M41: =M38+M39-M40 -> 1829.3622 | ... Q41: =Q38+Q39-Q40 -> 2279.5592
B42: 14 | C42: 息税前利润 | D42: =SUM(E42:Q42) -> 4971.2833 | F42: =F33+F37+F38 -> 2150.1895 | G42: =G33+G37+G38 -> 356.87025 | H42: =H33+H37+H38 -> 338.75189 | I42: =I33+I37+I38 -> 297.00687 | J42: =J33+J37+J38 -> 276.57574 | K42: =K33+K37+K38 -> 264.57355 | L42: =L33+L37+L38 -> 250.86626 | M42: =M33+M37+M38 -> 239.3521 | ... Q42: =Q33+Q37+Q38 -> 181.79654
...

Sheet 表3-项目现金流量表
B2: 项目投资现金流量表
B3: 人民币单位：万元
B4: 序号 | C4: 项目 | D4: 合计 | E4: 建设期 | F4: 计算期
E5: 第1年 | F5: 第2年 | G5: 第3年 | H5: 第4年 | I5: 第5年 | J5: 第6年 | K5: 第7年 | L5: 第8年 | M5: 第9年 | N5: 第10年 | O5: 第11年 | P5: 第12年 | Q5: 第13年
B6: 1 | C6: 现金流入 | D6: =SUM(E6:Q6) -> 43780.937 | E6: =E7+E8+E9 -> 0 | F6: =F7+F8+F9 -> 5596.8385 | G6: =G7+G8+G9 -> 3552.748 | H6: =H7+H8+H9 -> 3512.6657 | I6: =I7+I8+I9 -> 3483.272 | J6: =J7+J8+J9 -> 3449.8701 | K6: =K7+K8+K9 -> 3425.8208 | L6: =L7+L8+L9 -> 3396.4271 | ... Q6: =Q7+Q8+Q9 -> 4011.3994
B7: 1.1 | C7: 销售收入（含税） | D7: =SUM(E7:Q7) -> 43055.07 | E7: ='表2-利润与利润分配表'!E23 -> 0 | F7: ='表2-利润与利润分配表'!F23 -> 5596.8385 | G7: ='表2-利润与利润分配表'!G23 -> 3552.748 | H7: ='表2-利润与利润分配表'!H23 -> 3512.6657 | I7: ='表2-利润与利润分配表'!I23 -> 3483.272 | J7: ='表2-利润与利润分配表'!J23 -> 3449.8701 | K7: ='表2-利润与利润分配表'!K23 -> 3425.8208 | L7: ='表2-利润与利润分配表'!L23 -> 3396.4271 | ... Q7: ='表2-利润与利润分配表'!Q23 -> 3285.5328
B8: 1.2 | C8: 回收固定资产余值 | D8: =SUM(E8:Q8) -> 725.86664 | Q8: =分类折旧!L77*0.05 -> 725.86664
B9: 1.3 | C9: 回收流动资金 | D9: =SUM(E9:Q9) -> 0
B10: 2 | C10: 现金流出 | D10: =SUM(E10:Q10) -> 37396.108 | E10: =E11+E12+E13+E14+E15+E16 -> 15846.259 | F10: =F11+F12+F13+F14+F15+F16 -> 1653.4761 | G10: =G11+G12+G13+G14+G15+G16 -> 1637.8657 | H10: =H11+H12+H13+H14+H15+H16 -> 1633.9551 | I10: =I11+I12+I13+I14+I15+I16 -> 1885.4413 | J10: =J11+J12+J13+J14+J15+J16 -> 1874.7268 | K10: =K11+K12+K13+K14+K15+K16 -> 1864.3042 | L10: =L11+L12+L13+L14+L15+L16 -> 1850.6034 | ... Q10: =Q11+Q12+Q13+Q14+Q15+Q16 -> 1816.2698
B11: 2.1 | C11: 建设资金 | D11: =SUM(E11:Q11) -> 15846.259 | E11: ='表1-投资计划与资金筹措表'!E7 -> 15846.259 | F11: ='表1-投资计划与资金筹措表'!F7 -> 0
B12: 2.2 | C12: 流动资金 | D12: =SUM(E12:Q12) -> 0
B13: 2.3 | C13: 经营成本 | D13: =SUM(E13:Q13) -> 19073.791 | E13: ='表6-运营成本费用表'!E17 -> 0 | F13: ='表6-运营成本费用表'!F17 -> 1653.4761 | G13: ='表6-运营成本费用表'!G17 -> 1637.8657 | H13: ='表6-运营成本费用表'!H17 -> 1618.9 | I13: ='表6-运营成本费用表'!I17 -> 1606.3425 | J13: ='表6-运营成本费用表'!J17 -> 1597.4048 | K13: ='表6-运营成本费用表'!K17 -> 1588.2614 | L13: ='表6-运营成本费用表'!L17 -> 1576.1241 | ... Q13: ='表6-运营成本费用表'!Q17 -> 1547.6892
B14: 2.4 | C14: 当期缴纳增值税 | D14: =SUM(E14:Q14) -> 2210.7667 | E14: ='表2-利润与利润分配表'!E29 -> 0 | F14: ='表2-利润与利润分配表'!F29 -> 0 | G14: ='表2-利润与利润分配表'!G29 -> 0 | H14: ='表2-利润与利润分配表'!H29 -> 13.442053 | I14: ='表2-利润与利润分配表'!I29 -> 249.19536 | J14: ='表2-利润与利润分配表'!J29 -> 247.609 | K14: ='表2-利润与利润分配表'!K29 -> 246.46681 | L14: ='表2-利润与利润分配表'!L29 -> 245.07081 | ... Q14: ='表2-利润与利润分配表'!Q29 -> 239.80406
B15: 2.5 | C15: 销售税金及附加 | D15: =SUM(E15:Q15) -> 265.29201 | E15: ='表2-利润与利润分配表'!E30 -> 0 | F15: ='表2-利润与利润分配表'!F30 -> 0 | G15: ='表2-利润与利润分配表'!G30 -> 0 | H15: ='表2-利润与利润分配表'!H30 -> 1.6130464 | I15: ='表2-利润与利润分配表'!I30 -> 29.903444 | J15: ='表2-利润与利润分配表'!J30 -> 29.71308 | K15: ='表2-利润与利润分配表'!K30 -> 29.576017 | L15: ='表2-利润与利润分配表'!L30 -> 29.408497 | ... Q15: ='表2-利润与利润分配表'!Q30 -> 28.776488
B16: 2.6 | C16: 维持运营投资
B17: 3 | C17: 所得税前净现金流量 | D17: =SUM(E17:Q17) -> 6384.8288 | E17: =E6-E10 -> -15846.259 | F17: =F6-F10 -> 3943.3624 | G17: =G6-G10 -> 1914.8823 | H17: =H6-H10 -> 1878.7107 | I17: =I6-I10 -> 1597.8308 | J17: =J6-J10 -> 1575.1433 | K17: =K6-K10 -> 1561.5166 | L17: =L6-L10 -> 1545.8237 | ... Q17: =Q6-Q10 -> 2195.1296
B18: 4 | C18: 累计所得税前净现金流量 | D18: =Q18 -> 6384.8288 | E18: =E17 -> -15846.259 | F18: =E18+F17 -> -11902.896 | G18: =F18+G17 -> -9988.0139 | H18: =G18+H17 -> -8109.3032 | I18: =H18+I17 -> -6511.4724 | J18: =I18+J17 -> -4936.3291 | K18: =J18+K17 -> -3374.8126 | L18: =K18+L17 -> -1828.9889 | M18: =L18+M17 -> -296.12341 | ... Q18: =P18+Q17 -> 6384.8288
B19: 5 | C19: 调整所得税 | D19: =SUM(E19:Q19) -> 1242.8208 | E19: ='表2-利润与利润分配表'!E43 -> 0 | F19: ='表2-利润与利润分配表'!F43 -> 537.54737 | G19: ='表2-利润与利润分配表'!G43 -> 89.217563 | H19: ='表2-利润与利润分配表'!H43 -> 84.687972 | I19: ='表2-利润与利润分配表'!I43 -> 74.251718 | J19: ='表2-利润与利润分配表'!J43 -> 69.143935 | K19: ='表2-利润与利润分配表'!K43 -> 66.143388 | L19: ='表2-利润与利润分配表'!L43 -> 62.716565 | ... Q19: ='表2-利润与利润分配表'!Q43 -> 45.449134
B20: 6 | C20: 所得税后净现金流量 | D20: =SUM(E20:Q20) -> 5142.008 | E20: =E17-E19 -> -15846.259 | F20: =F17-F19 -> 3405.815 | G20: =G17-G19 -> 1825.6648 | H20: =H17-H19 -> 1794.0227 | I20: =I17-I19 -> 1523.579 | J20: =J17-J19 -> 1505.9994 | K20: =K17-K19 -> 1495.3732 | L20: =L17-L19 -> 1483.1071 | ... Q20: =Q17-Q19 -> 2149.6805
B21: 7 | C21: 累计所得税后净现金流量 | D21: =Q21 -> 5142.008 | E21: =E20 -> -15846.259 | F21: =E21+F20 -> -12440.444 | G21: =F21+G20 -> -10614.779 | H21: =G21+H20 -> -8820.7561 | I21: =H21+I20 -> -7297.1771 | J21: =I21+J20 -> -5791.1777 | K21: =J21+K20 -> -4295.8045 | L21: =K21+L20 -> -2812.6974 | M21: =L21+M20 -> -1339.6699 | ... Q21: =P21+Q20 -> 5142.008
C24: 全投资所得税前内部收益率 | D24: =IRR(E17:Q17) -> 0.06376743 | K24: =IRR(E17:Q17) -> 0.06376743
C25: 全投资所得税后内部收益率 | D25: =IRR(E20:Q20) -> 0.050775418 | K25: =IRR(E20:Q20) -> 0.050775418
C27: 年数 | E27: 1 | F27: 2 | G27: 3 | H27: 4 | I27: 5 | J27: 6 | K27: 7 | L27: 8 | M27: 9 | N27: 10 | O27: 11 | P27: 12 | Q27: 13
E28: 0 | F28: =IF(AND(F18>0,E18<0),ABS(E18)/F17,0) -> 0 | G28: =IF(AND(G18>0,F18<0),ABS(F18)/G17,0) -> 0 | H28: =IF(AND(H18>0,G18<0),ABS(G18)/H17,0) -> 0 | I28: =IF(AND(I18>0,H18<0),ABS(H18)/I17,0) -> 0 | J28: =IF(AND(J18>0,I18<0),ABS(I18)/J17,0) -> 0 | K28: =IF(AND(K18>0,J18<0),ABS(J18)/K17,0) -> 0 | L28: =IF(AND(L18>0,K18<0),ABS(K18)/L17,0) -> 0 | M28: =IF(AND(M18>0,L18<0),ABS(L18)/M17,0) -> 0 | ... Q28: =IF(AND(Q18>0,P18<0),ABS(P18)/Q17,0) -> 0
C29: 投资回收期（含建设期）（税前） | D29: {=INDEX(_xlfn._xlws.FILTER(E29:Q29,E29:Q29>0),1)} -> 9.1963532 | E29: =IF(E28>0,E27-1+E28,0) -> 0 | F29: =IF(F28>0,F27-1+F28,0) -> 0 | G29: =IF(G28>0,G27-1+G28,0) -> 0 | H29: =IF(H28>0,H27-1+H28,0) -> 0 | I29: =IF(I28>0,I27-1+I28,0) -> 0 | J29: =IF(J28>0,J27-1+J28,0) -> 0 | K29: =IF(K28>0,K27-1+K28,0) -> 0 | L29: =IF(L28>0,L27-1+L28,0) -> 0 | ... Q29: =IF(Q28>0,Q27-1+Q28,0) -> 0

Sheet 表4-资本金现金流量表
B2: 项目资本金现金流量表
B3: 人民币单位：万元
B4: 序号 | C4: 项目 | D4: 合计 | E4: 建设期 | F4: 计算期
E5: 第1年 | F5: 第2年 | G5: 第3年 | H5: 第4年 | I5: 第5年 | J5: 第6年 | K5: 第7年 | L5: 第8年 | M5: 第9年 | N5: 第10年 | O5: 第11年 | P5: 第12年 | Q5: 第13年
B6: 1 | C6: 现金流入 | D6: =SUM(E6:Q6) -> 43780.937 | E6: =E7+E8+E9 -> 0 | F6: =F7+F8+F9 -> 5596.8385 | G6: =G7+G8+G9 -> 3552.748 | H6: =H7+H8+H9 -> 3512.6657 | I6: =I7+I8+I9 -> 3483.272 | J6: =J7+J8+J9 -> 3449.8701 | K6: =K7+K8+K9 -> 3425.8208 | L6: =L7+L8+L9 -> 3396.4271 | ... Q6: =Q7+Q8+Q9 -> 4011.3994
B7: 1.1 | C7: 销售收入（含税） | D7: =SUM(E7:Q7) -> 43055.07 | E7: ='表2-利润与利润分配表'!E23 -> 0 | F7: ='表2-利润与利润分配表'!F23 -> 5596.8385 | G7: ='表2-利润与利润分配表'!G23 -> 3552.748 | H7: ='表2-利润与利润分配表'!H23 -> 3512.6657 | I7: ='表2-利润与利润分配表'!I23 -> 3483.272 | J7: ='表2-利润与利润分配表'!J23 -> 3449.8701 | K7: ='表2-利润与利润分配表'!K23 -> 3425.8208 | L7: ='表2-利润与利润分配表'!L23 -> 3396.4271 | ... Q7: ='表2-利润与利润分配表'!Q23 -> 3285.5328
B8: 1.3 | C8: 回收固定资产余值 | D8: =SUM(E8:Q8) -> 725.86664 | Q8: ='表3-项目现金流量表'!Q8 -> 725.86664
B9: 1.4 | C9: 回收流动资金 | D9: =SUM(E9:Q9) -> 0
B10: 2 | C10: 现金流出 | D10: =SUM(E10:Q10) -> 40024.703 | E10: =D11+E12+E13+E14+E15+E16+E17+E18 -> 3207.2827 | F10: =F11+F12+F13+F14+F15+F16+F17+F18 -> 3157.4416 | G10: =G11+G12+G13+G14+G15+G16+G17+G18 -> 3141.8312 | H10: =H11+H12+H13+H14+H15+H16+H17+H18 -> 3137.9206 | I10: =I11+I12+I13+I14+I15+I16+I17+I18 -> 3390.5995 | J10: =J11+J12+J13+J14+J15+J16+J17+J18 -> 3382.7121 | K10: =K11+K12+K13+K14+K15+K16+K17+K18 -> 3375.5125 | L10: =L11+L12+L13+L14+L15+L16+L17+L18 -> 3375.3576 | M10: =M11+M12+M13+M14+M15+M16+M17+M18 -> 3374.0819 | ... Q10: =Q11+Q12+Q13+Q14+Q15+Q16+Q17+Q18 -> 1861.7189
B11: 2.1 | C11: 资本金支出 | D11: =SUM(E11:Q11) -> 3207.2827 | E11: ='表1-投资计划与资金筹措表'!E10 -> 3207.2827
B12: 2.2 | C12: 偿还借款本金 | D12: =SUM(J12:Q12) -> 8147.2692 | E12: ='表5-借款还本付息表'!E20 -> 0 | F12: ='表5-借款还本付息表'!F20 -> 1119.0916 | G12: ='表5-借款还本付息表'!G20 -> 1152.6643 | H12: ='表5-借款还本付息表'!H20 -> 1187.2443 | I12: ='表5-借款还本付息表'!I20 -> 1222.8616 | J12: ='表5-借款还本付息表'!J20 -> 1259.5474 | K12: ='表5-借款还本付息表'!K20 -> 1297.3339 | L12: ='表5-借款还本付息表'!L20 -> 1336.2539 | ... Q12: ='表5-借款还本付息表'!Q20 -> -3.9344741e-13
B13: 2.3 | C13: 偿还借款利息 | D13: =SUM(E13:Q13) -> 2210.5243 | E13: ='表5-借款还本付息表'!E19 -> 0 | F13: ='表5-借款还本付息表'!F19 -> 384.87393 | G13: ='表5-借款还本付息表'!G19 -> 351.30118 | H13: ='表5-借款还本付息表'!H19 -> 316.72125 | I13: ='表5-借款还本付息表'!I19 -> 281.10392 | J13: ='表5-借款还本付息表'!J19 -> 244.41807 | K13: ='表5-借款还本付息表'!K19 -> 206.63165 | L13: ='表5-借款还本付息表'!L19 -> 167.71164 | ... Q13: ='表5-借款还本付息表'!Q19 -> 3.9344741e-13
B14: 2.4 | C14: 经营成本 | D14: =SUM(E14:Q14) -> 19073.791 | E14: ='表6-运营成本费用表'!E17 -> 0 | F14: ='表6-运营成本费用表'!F17 -> 1653.4761 | G14: ='表6-运营成本费用表'!G17 -> 1637.8657 | H14: ='表6-运营成本费用表'!H17 -> 1618.9 | I14: ='表6-运营成本费用表'!I17 -> 1606.3425 | J14: ='表6-运营成本费用表'!J17 -> 1597.4048 | K14: ='表6-运营成本费用表'!K17 -> 1588.2614 | L14: ='表6-运营成本费用表'!L17 -> 1576.1241 | ... Q14: ='表6-运营成本费用表'!Q17 -> 1547.6892
B15: 2.5 | C15: 缴纳当期增值税 | D15: =SUM(E15:Q15) -> 2210.7667 | E15: ='表2-利润与利润分配表'!E29 -> 0 | F15: ='表2-利润与利润分配表'!F29 -> 0 | G15: ='表2-利润与利润分配表'!G29 -> 0 | H15: ='表2-利润与利润分配表'!H29 -> 13.442053 | I15: ='表2-利润与利润分配表'!I29 -> 249.19536 | J15: ='表2-利润与利润分配表'!J29 -> 247.609 | K15: ='表2-利润与利润分配表'!K29 -> 246.46681 | L15: ='表2-利润与利润分配表'!L29 -> 245.07081 | ... Q15: ='表2-利润与利润分配表'!Q29 -> 239.80406
B16: 2.6 | C16: 销售税金及附加 | D16: =SUM(E16:Q16) -> 265.29201 | E16: ='表2-利润与利润分配表'!E30 -> 0 | F16: ='表2-利润与利润分配表'!F30 -> 0 | G16: ='表2-利润与利润分配表'!G30 -> 0 | H16: ='表2-利润与利润分配表'!H30 -> 1.6130464 | I16: ='表2-利润与利润分配表'!I30 -> 29.903444 | J16: ='表2-利润与利润分配表'!J30 -> 29.71308 | K16: ='表2-利润与利润分配表'!K30 -> 29.576017 | L16: ='表2-利润与利润分配表'!L30 -> 29.408497 | ... Q16: ='表2-利润与利润分配表'!Q30 -> 28.776488
B17: 2.7 | C17: 缴纳所得税 | D17: =SUM(E17:Q17) -> 227.91547 | E17: ='表2-利润与利润分配表'!E37 -> 0 | F17: ='表2-利润与利润分配表'!F37 -> 0 | G17: ='表2-利润与利润分配表'!G37 -> 0 | H17: ='表2-利润与利润分配表'!H37 -> 0 | I17: ='表2-利润与利润分配表'!I37 -> 1.1927212 | J17: ='表2-利润与利润分配表'!J37 -> 4.0197081 | K17: ='表2-利润与利润分配表'!K37 -> 7.2427378 | L17: ='表2-利润与利润分配表'!L37 -> 20.788656 | ... Q17: ='表2-利润与利润分配表'!Q37 -> 45.449134
B18: 2.8 | C18: 维持运营投资 | D18: =SUM(E18:Q18) -> 0 | P18: ='表1-投资计划与资金筹措表'!P10 -> 0
B19: 3 | C19: 净现金流量 | D19: =SUM(E19:Q19) -> 3756.234 | E19: =E6-E10 -> -3207.2827 | F19: =F6-F10 -> 2439.3969 | G19: =G6-G10 -> 410.9168 | H19: =H6-H10 -> 374.74514 | I19: =I6-I10 -> 92.67252 | J19: =J6-J10 -> 67.158072 | K19: =K6-K10 -> 50.3083 | L19: =L6-L10 -> 21.069518 | ... Q19: =Q6-Q10 -> 2149.6805
E21: 总利润 | F21: 年平均利润
A22: 静态投资 | C22: 12年资本金内部收益率 | D22: =IRR(E19:Q19) -> 0.17967327 | E22: =SUM('表2-利润与利润分配表'!F34:O34) -> 2386.1844 | F22: =E22/10 -> 238.61844
A23: 动态投资

Sheet 表5-借款还本付息表
B3: 借款还本付息表
B4: 序号 | C4: 项目 | D4: 合计 | E4: 建设期
E5: 第1年 | F5: 第2年 | G5: 第3年 | H5: 第4年 | I5: 第5年 | J5: 第6年 | K5: 第7年 | L5: 第8年 | M5: 第9年 | N5: 第10年 | O5: 第11年 | P5: 第12年 | Q5: 第13年
B6: 1 | C6: 长期借款：
C7: 年初借款本金 | D7: - | F7: =E8 -> 12829.131 | G7: =F14 -> 11710.039 | H7: =G14 -> 10557.375 | I7: =H14 -> 9370.1308 | J7: =I14 -> 8147.2692 | K7: =J14 -> 6887.7217 | L7: =K14 -> 5590.3878 | M7: =L14 -> 4254.134 | N7: =M14 -> 2877.7924 | ... Q7: =P14 -> 1.3114914e-11
C8: 本年新增借款 | D8: =SUM(E8:Q8) -> 12829.131 | E8: ='表1-投资计划与资金筹措表'!E11 -> 12829.131
C9: 本年应计利息 | D9: =SUM(E9:Q9) -> 2210.5243 | F9: =F7*F12 -> 384.87393 | G9: =G7*G12 -> 351.30118 | H9: =H7*H12 -> 316.72125 | I9: =I7*I12 -> 281.10392 | J9: =J7*J12 -> 244.41807 | K9: =K7*K12 -> 206.63165 | L9: =L7*L12 -> 167.71164 | M9: =M7*M12 -> 127.62402 | ... Q9: =Q7*Q12 -> 3.9344741e-13
C10: 本年还本付息 | D10: =SUM(E10:Q10) -> 15039.655 | F10: =IF(输入参数!E19="等额本金",SUM(F9,F11),'表1-投资计划与资金筹措表'!E11*输入参数!E20*(1+输入参数!E20)^10/((1+输入参数!E20)^10-1)) -> 1503.9655 | G10: =IF(输入参数!E19="等额本金",G9+G11,F10) -> 1503.9655 | H10: =IF(输入参数!E19="等额本金",H9+H11,F10) -> 1503.9655 | I10: =IF(输入参数!E19="等额本金",I9+I11,F10) -> 1503.9655 | J10: =IF(输入参数!E19="等额本金",J9+J11,F10) -> 1503.9655 | K10: =IF(输入参数!E19="等额本金",K9+K11,F10) -> 1503.9655 | L10: =IF(输入参数!E19="等额本金",L9+L11,F10) -> 1503.9655 | M10: =IF(输入参数!E19="等额本金",M9+M11,F10) -> 1503.9655 | N10: =IF(输入参数!E19="等额本金",N9+N11,F10) -> 1503.9655 | O10: =IF(输入参数!E19="等额本金",O9+O11,F10) -> 1503.9655 | P10: =$O$8*输入参数!E20*(1+输入参数!E20)^10/((1+输入参数!E20)^10-1) -> 0 | Q10: =$P$10 -> 0
C11: 本年偿还本金 | D11: =SUM(E11:Q11) -> 12829.131 | F11: =IF(输入参数!E19="等额本金",'表1-投资计划与资金筹措表'!D11/10,F10-F9) -> 1119.0916 | G11: =IF(输入参数!E19="等额本金",F11,G10-G9) -> 1152.6643 | H11: =IF(输入参数!E19="等额本金",F11,H10-H9) -> 1187.2443 | I11: =IF(输入参数!E19="等额本金",F11,I10-I9) -> 1222.8616 | J11: =IF(输入参数!E19="等额本金",F11,J10-J9) -> 1259.5474 | K11: =IF(输入参数!E19="等额本金",F11,K10-K9) -> 1297.3339 | L11: =IF(输入参数!E19="等额本金",F11,L10-L9) -> 1336.2539 | M11: =IF(输入参数!E19="等额本金",F11,M10-M9) -> 1376.3415 | N11: =IF(输入参数!E19="等额本金",F11,N10-N9) -> 1417.6317 | O11: =IF(输入参数!E19="等额本金",F11,O10-O9) -> 1460.1607 | P11: =IF(输入参数!F19="等额本金",G11,P10-P9) -> -3.8198777e-13 | Q11: =IF(输入参数!G19="等额本金",H11,Q10-Q9) -> -3.9344741e-13
C12: 长期借款利率： | D12: =输入参数!E20 -> 0.03 | F12: =D12 -> 0.03 | G12: =F12 -> 0.03 | H12: =G12 -> 0.03 | I12: =H12 -> 0.03 | J12: =I12 -> 0.03 | K12: =J12 -> 0.03 | L12: =K12 -> 0.03 | M12: =L12 -> 0.03 | N12: =M12 -> 0.03 | ... Q12: =P12 -> 0.03
C13: 本年偿还利息 | D13: =SUM(E13:Q13) -> 2210.5243 | F13: =F9 -> 384.87393 | G13: =G9 -> 351.30118 | H13: =H9 -> 316.72125 | I13: =I9 -> 281.10392 | J13: =J9 -> 244.41807 | K13: =K9 -> 206.63165 | L13: =L9 -> 167.71164 | M13: =M9 -> 127.62402 | ... Q13: =Q9 -> 3.9344741e-13
C14: 期末借款余额 | E14: =E7+E8-E11 -> 12829.131 | F14: =F7+F8-F11 -> 11710.039 | G14: =G7+G8-G11 -> 10557.375 | H14: =H7+H8-H11 -> 9370.1308 | I14: =I7+I8-I11 -> 8147.2692 | J14: =J7+J8-J11 -> 6887.7217 | K14: =K7+K8-K11 -> 5590.3878 | L14: =L7+L8-L11 -> 4254.134 | ... Q14: =Q7+Q8-Q11 -> 1.3508361e-11
B15: 2 | C15: 短期借款
B16: 2.1 | C16: 短期借款本金 | D16: =SUM(E16:Q16) -> 0
B17: 2.2 | C17: 短期借款利息 | D17: =SUM(E17:Q17) -> 0
B18: 2.3 | C18: 偿还短期借款本金 | D18: =SUM(E18:Q18) -> 0
B19: 偿还利息合计 | D19: =SUM(E19:Q19) -> 2210.5243 | E19: =E13+E17 -> 0 | F19: =F13+F17 -> 384.87393 | G19: =G13+G17 -> 351.30118 | H19: =H13+H17 -> 316.72125 | I19: =I13+I17 -> 281.10392 | J19: =J13+J17 -> 244.41807 | K19: =K13+K17 -> 206.63165 | L19: =L13+L17 -> 167.71164 | ... Q19: =Q13+Q17 -> 3.9344741e-13
B20: 偿还本金合计 | D20: =SUM(E20:Q20) -> 12829.131 | E20: =E11+E18 -> 0 | F20: =F11+F18 -> 1119.0916 | G20: =G11+G18 -> 1152.6643 | H20: =H11+H18 -> 1187.2443 | I20: =I11+I18 -> 1222.8616 | J20: =J11+J18 -> 1259.5474 | K20: =K11+K18 -> 1297.3339 | L20: =L11+L18 -> 1336.2539 | ... Q20: =Q11+Q18 -> -3.9344741e-13

Sheet 表6-运营成本费用表
B3: 运营成本费用表
B5: 序号 | C5: 项目名称 | D5: 合计 | E5: 建设期
E6: 第1年 | F6: 第2年 | G6: 第3年 | H6: 第4年 | I6: 第5年 | J6: 第6年 | K6: 第7年 | L6: 第8年 | M6: 第9年 | N6: 第10年 | O6: 第11年 | P6: 第12年 | Q6: 第13年
B7: 1 | C7: 折旧费 | D7: =SUM(E7:Q7) -> 13791.466 | F7: =IF(输入参数!$E$23="直线折旧",F21,手动输入参数表!D14) -> 1149.2888 | G7: =IF(输入参数!$E$23="直线折旧",G21,手动输入参数表!E14) -> 1149.2888 | H7: =IF(输入参数!$E$23="直线折旧",H21,手动输入参数表!F14) -> 1149.2888 | I7: =IF(输入参数!$E$23="直线折旧",I21,手动输入参数表!G14) -> 1149.2888 | J7: =IF(输入参数!$E$23="直线折旧",J21,手动输入参数表!H14) -> 1149.2888 | K7: =IF(输入参数!$E$23="直线折旧",K21,手动输入参数表!I14) -> 1149.2888 | L7: =IF(输入参数!$E$23="直线折旧",L21,手动输入参数表!J14) -> 1149.2888 | M7: =IF(输入参数!$E$23="直线折旧",M21,手动输入参数表!K14) -> 1149.2888 | ... Q7: =IF(输入参数!$E$23="直线折旧",Q21,手动输入参数表!O14) -> 1149.2888
B8: 2 | C8: 运维费 | D8: =SUM(E8:Q8) -> 1086.1196 | F8: =运维费!C20 -> 78.349018 | G8: =运维费!D20 -> 84.186273 | H8: =运维费!E20 -> 84.186273 | I8: =运维费!F20 -> 84.186273 | J8: =运维费!G20 -> 90.023528 | K8: =运维费!H20 -> 90.023528 | L8: =运维费!I20 -> 90.023528 | M8: =运维费!J20 -> 90.023528 | ... Q8: =运维费!N20 -> 98.779409
B9: 3 | C9: 人工成本 | D9: =SUM(E9:Q9) -> 1873.3479 | F9: =输入参数!E29*输入参数!E30 -> 132 | G9: =F9*1.03 -> 135.96 | H9: =G9*1.03 -> 140.0388 | I9: =H9*1.03 -> 144.23996 | J9: =I9*1.03 -> 148.56716 | K9: =J9*1.03 -> 153.02418 | L9: =K9*1.03 -> 157.6149 | M9: =L9*1.03 -> 162.34335 | N9: =M9*1.03 -> 167.21365 | ... Q9: =P9*1.03 -> 182.71887
B10: 4 | C10: 保险费 | D10: =SUM(E10:Q10) -> 322.62273 | F10: ='表1-投资计划与资金筹措表'!D6*输入参数!E33 -> 24.054621 | G10: =F10*1.02 -> 24.535713 | H10: =G10*1.02 -> 25.026427 | I10: =H10*1.02 -> 25.526956 | J10: =I10*1.02 -> 26.037495 | K10: =J10*1.02 -> 26.558245 | L10: =K10*1.02 -> 27.08941 | M10: =L10*1.02 -> 27.631198 | N10: =M10*1.02 -> 28.183822 | ... Q10: =P10*1.02 -> 29.908897
B11: 5 | C11: 利息支出（万元） | D11: =SUM(E11:Q11) -> 2210.5243 | F11: ='表5-借款还本付息表'!F13 -> 384.87393 | G11: ='表5-借款还本付息表'!G13 -> 351.30118 | H11: ='表5-借款还本付息表'!H13 -> 316.72125 | I11: ='表5-借款还本付息表'!I13 -> 281.10392 | J11: ='表5-借款还本付息表'!J13 -> 244.41807 | K11: ='表5-借款还本付息表'!K13 -> 206.63165 | L11: ='表5-借款还本付息表'!L13 -> 167.71164 | M11: ='表5-借款还本付息表'!M13 -> 127.62402 | ... Q11: ='表5-借款还本付息表'!Q13 -> 3.9344741e-13
B12: 6 | C12: 土地费用或土地使用税（万元/年) | D12: =SUM(E12:Q12) -> 422.40021 | F12: =输入参数!E36 -> 35.200018 | G12: =F12 -> 35.200018 | H12: =G12 -> 35.200018 | I12: =H12 -> 35.200018 | J12: =I12 -> 35.200018 | K12: =J12 -> 35.200018 | L12: =K12 -> 35.200018 | M12: =L12 -> 35.200018 | N12: =M12 -> 35.200018 | ... Q12: =P12 -> 35.200018
B13: 7 | C13: 其他费用 | D13: =SUM(E13:Q13) -> 15369.3 | F13: =SUM(F14:F15) -> 1383.8725 | G13: =SUM(G14:G15) -> 1357.9837 | H13: =SUM(H14:H15) -> 1334.4484 | I13: =SUM(I14:I15) -> 1317.1893 | J13: =SUM(J14:J15) -> 1297.5766 | K13: =SUM(K14:K15) -> 1283.4554 | L13: =SUM(L14:L15) -> 1266.1962 | M13: =SUM(M14:M15) -> 1253.6441 | ... Q13: =SUM(Q14:Q15) -> 1201.082
B14: 7.1 | C14: 应列未列的其他成本费用 | D14: =SUM(E14:Q14) -> 0 | F14: =输入参数!E32 -> 0 | G14: =F14*(1+0%) -> 0 | H14: =G14 -> 0 | I14: =H14 -> 0 | J14: =I14 -> 0 | K14: =J14 -> 0 | L14: =K14 -> 0 | M14: =L14 -> 0 | N14: =M14 -> 0 | O14: =N14 -> 0 | ... Q14: =P14 -> 0
B15: 7.2 | C15: 购电电费 | D15: =SUM(J15:Q15) -> 9975.8062 | F15: =手动输入参数表!D32 -> 1383.8725 | G15: =手动输入参数表!E32 -> 1357.9837 | H15: =手动输入参数表!F32 -> 1334.4484 | I15: =手动输入参数表!G32 -> 1317.1893 | J15: =手动输入参数表!H32 -> 1297.5766 | K15: =手动输入参数表!I32 -> 1283.4554 | L15: =手动输入参数表!J32 -> 1266.1962 | M15: =手动输入参数表!K32 -> 1253.6441 | ... Q15: =手动输入参数表!O32 -> 1201.082
B16: 8 | C16: 总成本费用 | D16: =SUM(E16:Q16) -> 35075.781 | F16: =F7+F9+F11+F13+F8+F10+F12 -> 3187.6389 | G16: =G7+G9+G11+G13+G8+G10+G12 -> 3138.4557 | H16: =H7+H9+H11+H13+H8+H10+H12 -> 3084.9101 | I16: =I7+I9+I11+I13+I8+I10+I12 -> 3036.7352 | J16: =J7+J9+J11+J13+J8+J10+J12 -> 2991.1117 | K16: =K7+K9+K11+K13+K8+K10+K12 -> 2944.1819 | L16: =L7+L9+L11+L13+L8+L10+L12 -> 2893.1246 | M16: =M7+M9+M11+M13+M8+M10+M12 -> 2845.7551 | ... Q16: =Q7+Q9+Q11+Q13+Q8+Q10+Q12 -> 2696.9781
B17: 9 | C17: 经营成本 | D17: =SUM(E17:Q17) -> 19073.791 | F17: =F16-F7-F11 -> 1653.4761 | G17: =G16-G7-G11 -> 1637.8657 | H17: =H16-H7-H11 -> 1618.9 | I17: =I16-I7-I11 -> 1606.3425 | J17: =J16-J7-J11 -> 1597.4048 | K17: =K16-K7-K11 -> 1588.2614 | L17: =L16-L7-L11 -> 1576.1241 | M17: =M16-M7-M11 -> 1568.8422 | ... Q17: =Q16-Q7-Q11 -> 1547.6892
C20: 投资规模
C21: 转资后固定资产原值： | D21: ='表2-利润与利润分配表'!D46 -> 14593.136 | E21: 每年直线折旧额 | F21: =D21*0.95/20 -> 693.17398
C22: 可抵扣进项税额 | D22: =输入参数!E22 -> 1443.2772
F24: 0.2 | G24: =F24*1.02 -> 0.204 | H24: =G24*1.02 -> 0.20808 | I24: =H24*1.02 -> 0.2122416 | J24: =I24*1.02 -> 0.21648643 | K24: =J24*1.02 -> 0.22081616 | L24: =K24*1.02 -> 0.22523248 | M24: =L24*1.02 -> 0.22973713 | N24: =M24*1.02 -> 0.23433188 | ... Q24: =P24*1.02 -> 0.24867486
